Workbook

Sheet BALANCE
A1: BALANCE AL MES DE FEBRERO DE 2026
A3: N° | B3: APELLIDOS Y NOMBRES | C3: MESES | D3: FECHA DE PRÉSTAMO | E3: PRÉSTAMO ACUMULADO | F3: INTERES MENSUAL ACTUAL | G3: INTERES PARCIAL ACUMULADO | H3: INTERES PROYECTADO ACUMULADO | I3: SALDO ACTUAL
A4: 1 | B4: ALIAGA ARAUJO, Angel F. | C4: 84 MESES | D4: 45625 | E4: S/43,427.8 | F4: S/209.6 | G4: S/10,310.8 | H4: S/17,542.6 | I4: S/20,663.6
A5: 2 | B5: ALVAREZ DIAZ, Rene | C5: 60 MESES | D5: 46081 | E5: S/29,153.1 | F5: - | G5: S/8,520.1 | H5: S/8,891.5 | I5: S/29,153.1
A6: 3 | B6: ARAUJO SANCHEZ, Magda M. | C6: 84 MESES | D6: 45806 | E6: S/59,233.2 | F6: S/391.5 | G6: S/15,699.6 | H6: S/30,380.2 | I6: S/38,632.4
A7: 4 | B7: BARRANTES ROJAS, Luis E. | C7: 72 MESES | D7: 45045 | E7: S/44,154.4 | F7: S/239.2 | G7: S/11,571.9 | H7: S/16,115.8 | I7: S/23,302.2
A8: 5 | B8: BAZAN VASQUEZ, Mirtha L. | C8: 60 MESES | D8: 45898 | E8: S/42,148.5 | F8: S/285.9 | G8: S/5,773.0 | H8: S/13,493.8 | I8: S/28,073.8
A9: 6 | B9: CABANILLAS YZQUIERDO, Jorge Luis | C9: 84 MESES | D9: 45806 | E9: S/41,477.1 | F9: S/320.3 | G9: S/7,682.0 | H9: S/19,691.6 | I9: S/31,608.4
A10: 7 | B10: CHAVEZ ALVAREZ, Jorge A. | C10: 84 MESES | D10: 45867 | E10: S/34,118.8 | F10: S/235.8 | G10: S/8,404.7 | H10: S/17,484.8 | I10: S/23,279.7
A11: 8 | B11: CHAVEZ ALVAREZ, Luis F. | C11: 60 MESES | D11: 46081 | E11: S/37,389.2 | F11: S/141.4 | G11: S/4,501.7 | H11: S/13,311.1 | I11: S/28,883.6
A12: 9 | B12: CHAVEZ CHAVEZ, Jorge E. | C12: 84 MESES | D12: 45837 | E12: S/56,293.4 | F12: S/422.8 | G12: S/11,727.5 | H12: S/27,794.2 | I12: S/41,731.6
A13: 10 | B13: CHAVEZ CHAVEZ, Pedro | C13: 36 MESES | D13: 45959 | E13: S/30,907.5 | F13: S/187.9 | G13: S/4,070.0 | H13: S/7,076.8 | I13: S/18,223.3
A14: 11 | B14: CHAVEZ MARIN Edwin F. | C14: 84 MESES | D14: 45929 | E14: S/63,280.7 | F14: S/502.3 | G14: S/10,990.1 | H14: S/30,832.2 | I14: S/49,604.6
A15: 12* | B15: CHAVEZ QUEVEDO, Melba G. | C15: 12 MESES | D15: 46051 | E15: S/53,453.9 | F15: S/257.4 | G15: S/4,447.4 | H15: S/5,863.4 | I15: S/23,595.4
A16: 13 | B16: CHAVEZ SALAZAR, María E. | C16: 84 MESES | D16: 45716 | E16: S/34,457.0 | F16: S/210.9 | G16: S/7,612.5 | H16: S/15,203.7 | I16: S/20,799.2
A17: 14 | B17: DIAZ ALBARRAN, Carlos F. | C17: 84 MESES | D17: 45259 | E17: S/33,883.7 | F17: S/234.0 | G17: S/7,732.8 | H17: S/14,400.0 | I17: S/22,991.9
A18: 15 | B18: DIAZ ALBARRAN, Juan S. | C18: 48 MESES | D18: 45837 | E18: S/29,666.4 | F18: S/175.8 | G18: S/4,648.2 | H18: S/8,164.7 | I18: S/17,152.7
A19: 16 | B19: DIAZ ALIAGA, Kevin A. | C19: 60 MESES | D19: 46081 | E19: S/32,964.1 | F19: S/127.2 | G19: S/3,287.6 | H19: S/10,327.9 | I19: S/23,085.0
A20: 17* | B20: DÍAZ QUIROZ, Maritza Y. | C20: 84 MESES | D20: 46051 | E20: S/45,768.7 | F20: S/330.0 | G20: S/9,801.1 | H20: S/23,496.3 | I20: S/32,609.2
A21: 18 | B21: DÍAZ VERA, Jackeline M. | C21: 72 MESES | D21: 45502 | E21: S/66,034.5 | F21: S/392.7 | G21: S/15,731.7 | H21: S/26,137.9 | I21: S/38,541.4
A22: 19 | B22: DÍAZ VERA, Tania J. | C22: 60 MESES | D22: 45716 | E22: S/59,208.6 | F22: S/326.8 | G22: S/14,724.5 | H22: S/22,567.0 | I22: S/32,008.5
A23: 20 | B23: MONTOYA CHÁVEZ, Wilser F. | C23: 84 MESES | D23: 45898 | E23: S/66,140.8 | F23: S/525.8 | G23: S/11,407.0 | H23: S/31,912.8 | I23: S/51,911.3
A24: 21 | B24: MONTOYA CRISOLOGO, Luis F. | C24: 60 MESES | D24: 45776 | E24: S/47,061.6 | F24: S/313.9 | G24: S/8,585.4 | H24: S/16,432.3 | I24: S/30,771.1
A25: 22 | B25: MONTOYA MACHUCA, Hugo D. | C25: 60 MESES | D25: 45958 | E25: S/29,080.9 | F25: S/194.2 | G25: S/4,868.8 | H25: S/10,307.0 | I25: S/19,080.2
A26: 23* | B26: PEREYRA CHAVEZ, Jhonatan G. | C26: 84 MESES | D26: 46051 | E26: S/34,971.7 | F26: S/210.0 | G26: S/6,960.7 | H26: S/18,758.8 | I26: S/20,751.4
A27: 24** | B27: PEREYRA RODRIGUEZ, Bertha E. | C27: 60 MESES | D27: 46020 | E27: S/33,557.2 | F27: S/218.6 | G27: S/4,013.0 | H27: S/10,352.4 | I27: S/21,492.0
A28: 25 | B28: PEREYRA RODRIGUEZ, Hilda L. | C28: 84 MESES | D28: 45837 | E28: S/33,058.1 | F28: S/211.1 | G28: S/6,328.8 | H28: S/14,349.1 | I28: S/20,835.5
A29: 26*** | B29: RONCAL ALBARRAN, Alejandro | C29: 36 MESES | D29: 45990 | E29: S/61,300.5 | F29: S/439.0 | G29: S/7,082.6 | H29: S/14,325.5 | I29: S/42,605.9
A30: 27 | B30: SANCHEZ ZAVALETA, Luis A. | C30: 84 MESES | D30: 45928 | E30: S/52,896.8 | F30: S/405.9 | G30: S/10,115.7 | H30: S/26,151.4 | I30: S/40,086.9
A31: 28 | B31: TAMBO RABANAL, Esperanza | C31: 84 MESES | D31: 45806 | E31: S/40,647.9 | F31: S/309.7 | G31: S/7,395.6 | H31: S/19,006.5 | I31: S/30,559.6
A32: 29 | B32: TAPIA DIAZ, Jhonatan E. | C32: 84 MESES | D32: 45928 | E32: S/50,061.6 | F32: S/285.0 | G32: S/10,329.8 | H32: S/21,586.0 | I32: S/28,144.0
A33: 30 | B33: VERA ARAUJO, Cristina | C33: 36 MESES | D33: 45686 | E33: S/40,896.4 | F33: S/143.1 | G33: S/8,064.5 | H33: S/12,581.6 | I33: S/24,415.6
A34: FEBRERO DE 2026 - TOTAL | E34: S/1,414,246.8 | F34: S/8,614.9 | G34: S/252,389.1 | H34: S/524,538.9 | I34: S/874,593.1

Sheet SOCIOS
A1: RELACIÓN DE PRÉSTAMOS DE LOS INTEGRANTES DE LA ASOCIACIÓN
A2: N° | B2: APELLIDOS Y NOMBRES | C2: N° MESES | D2: FECHA PRESTAMO | E2: SALDO | F2: MES/2026 | G2: REUNIÓN | H2: PERMISOS
A3: 1 | B3: ALIAGA ARAUJO, Angel Fernando | C3: 60 meses | D3: 45625 | E3: ='1'!G19 -> 20663.6 | G3: 46204 | H3: 46054
A4: 2 | B4: ALVAREZ DÍAZ, René | C4: 60 meses | D4: 46081 | E4: ='2'!G4 -> 29153.1 | F4: FEBRERO
A5: 3 | B5: ARAUJO SANCHEZ, Magda Mercedes | C5: 84 meses | D5: 45806 | E5: ='3'!G13 -> 38632.4 | G5: 46235 | H5: -
A6: 4 | B6: BARRANTES ROJAS, Luis Euler | C6: 72 meses | D6: 45045 | E6: ='4'!G38 -> 23302.2 | G6: 46266 | H6: 46054
A7: 5 | B7: BAZAN VASQUEZ, Mirtha Lusnilda | C7: 60 meses | D7: 45898 | E7: ='5'!G10 -> 28073.8 | G7: 46296 | H7: 46054
A8: 6 | B8: CABANILLAS YZQUIERDO, Jorge Luis | C8: 84 meses | D8: 45806 | E8: ='6'!G13 -> 31608.4 | G8: 46327 | H8: -
A9: 7 | B9: CHAVEZ ALVAREZ, Jorge Arturo | C9: 84 meses | D9: 45898 | E9: ='7'!G11 -> 23279.7 | G9: 46357 | H9: -
A10: 8 | B10: CHAVEZ ALVAREZ, Luis Fernando | C10: 60 meses | D10: 46081 | E10: ='8'!G69 -> 28883.6 | F10: FEBRERO | G10: 46388 | H10: -
A11: 9 | B11: CHAVEZ CHAVEZ, Jorge Emiliano | C11: 84 meses | D11: 45837 | E11: ='9'!G12 -> 41731.6 | G11: 46419 | H11: -
A12: 10 | B12: CHAVEZ CHAVEZ, Pedro | C12: 36 meses | D12: 45959 | E12: ='10'!G62 -> 18223.3 | G12: 46447 | H12: 46054
A13: 11 | B13: CHAVEZ MARIN Edwin Felix | C13: 84 meses | D13: 45929 | E13: ='11'!G9 -> 49604.6 | G13: 46478 | H13: 46054
A14: 12 | B14: CHAVEZ QUEVEDO, Melba Gladis | C14: 12 meses | D14: 46051 | E14: ='12'!G71 -> 23595.4 | F14: ENERO | G14: 46508 | H14: 45962
A15: 13 | B15: CHAVEZ SALAZAR, María Elizabeth | C15: 84 meses | D15: 29/02/2025 | E15: ='13'!G16 -> 20799.2 | G15: 46539 | H15: -
A16: 14 | B16: DIAZ ALBARRAN, Carlos Felipe | C16: 84 meses | D16: 45259 | E16: ='14'!G31 -> 22991.9 | G16: 46569 | H16: 46054
A17: 15 | B17: DIAZ ALBARRAN, Juan de la Salle | C17: 48 meses | D17: 45837 | E17: ='15'!G12 -> 17152.7 | G17: 21/12/2025 - 7 PM | H17: -
A18: 16 | B18: DIAZ ALIAGA, Kevin Airton | C18: 60 meses | D18: 46081 | E18: ='16'!G57 -> 23085 | F18: FEBRERO | G18: 46631 | H18: -
A19: 17 | B19: DÍAZ QUIROZ, Maritza Yolanda | C19: 84 meses | D19: 46051 | E19: ='17'!G95 -> 32609.2 | F19: ENERO | G19: 46661 | H19: -
A20: 18 | B20: DÍAZ VERA, Jackeline Magdalena | C20: 72 meses | D20: 45502 | E20: ='18'!G23 -> 38541.4 | G20: 46692 | H20: -
A21: 19 | B21: DÍAZ VERA, Tania Janet | C21: 60 meses | D21: 29/02/2025 | E21: ='19'!G16 -> 32008.5 | G21: 46722 | H21: -
A22: 20 | B22: MONTOYA CHÁVEZ, Wilser Filadelfo | C22: 84 meses | D22: 45898 | E22: ='20'!G10 -> 51911.3 | G22: 46784 | H22: NOVIEMBRE 2025 FEBRERO 2026
A23: 21 | B23: MONTOYA CRISOLOGO, Luis Fernando | C23: 60 meses | D23: 45776 | E23: ='21'!G14 -> 30771.1 | G23: 46813 | H23: 46054
A24: 22 | B24: MONTOYA MACHUCA, Hugo Delesmiro | C24: 60 meses | D24: 45959 | E24: ='22'!G75 -> 19080.2 | G24: 46844 | H24: 45962
A25: 23 | B25: PEREYRA CHAVEZ, Jhonatan Guillermo | C25: 84 meses | D25: 46051 | E25: ='23'!G71 -> 20751.4 | F25: ENERO | G25: 30/11/2025 - 7 PM | H25: -
A26: 24 | B26: PEREYRA RODRIGUEZ, Bertha Esther | C26: 60 meses | D26: 46020 | E26: ='24'!G60 -> 21492 | G26: NO SE REALIZÓ | H26: 46054
A27: 25 | B27: PEREYRA RODRIGUEZ, Hilda Lucila | C27: 84 meses | D27: 45837 | E27: ='25'!G12 -> 20835.5 | H27: 46054
A28: 26 | B28: RONCAL ALBARRAN, Alejandro | C28: 36 meses | D28: 45990 | E28: ='26'!G61 -> 42605.9 | G28: 28/02/2026 - 7 PM | H28: -
A29: 27 | B29: SANCHEZ ZAVALETA, Luis Alberto | C29: 84 meses | D29: 45929 | E29: ='27'!G9 -> 40086.9 | G29: 46082 | H29: -
A30: 28 | B30: TAMBO RABANAL, Esperanza | C30: 84 meses | D30: 45806 | E30: ='28'!G13 -> 30559.6 | G30: 46113 | H30: 46054
A31: 29 | B31: TAPIA DIAZ, Jhonatan Edinson | C31: 84 meses | D31: 45929 | E31: ='29'!G9 -> 28144 | G31: 46143 | H31: -
A32: 30 | B32: VERA ARAUJO, Cristina | C32: 36 meses | D32: 46081 | E32: ='30'!G46 -> 24415.6 | F32: FEBRERO | G32: 46174 | H32: -
A33: TOTAL | E33: =SUM(E3:E32) -> 874593.1
A34: ACCIONES POR SOCIO | E34: =E33/A32 -> 29153.103
A83: APORTACIÓN MARZO DE 2026
A84: RELACIÓN DE CUOTAS DE LOS INTEGRANTES DE LA ASOCIACIÓN
A85: N° | B85: APELLIDOS Y NOMBRES | C85: N° MESES | D85: FECHA | E85: PRÉSTAMO | F85: APORTACIÓN | G85: TOTAL
A86: 1 | B86: ALIAGA ARAUJO, Angel Fernando | C86: 60 meses | D86: 45625 | E86: S/506.1 | F86: S/150.0 | G86: S/656.1
A87: 2 | B87: ALVAREZ DÍAZ, René | C87: 60 meses | D87: 46081 | E87: S/777.4 | F87: S/150.0 | G87: S/927.4
A88: 3 | B88: ARAUJO SANCHEZ, Magda Mercedes | C88: 84 meses | D88: 45806 | E88: S/901.4 | F88: S/150.0 | G88: S/1,051.4
...

Sheet 1
A1: SOCIO: ANGEL FERNANDO ALIAGA ARAUJO
A2: NOVIEMBRE 2024 - PRÉSTAMO
A3: PLAZO | B3: FECHA | C3: PRÉSTAMO S/. | D3: INTERES | E3: ABONO DE CAPITAL | F3: CUOTA | G3: SALDO
A4: 0 | B4: 45625 | C4: =+J7 -> 25156.1 | D4: 0.01 | G4: =+C4 -> 25156.1
A5: 1 | B5: 45655 | D5: =+ROUND(G4*0.01,1) -> 251.6 | E5: =ROUNDUP($C$4/84,1) -> 299.5 | F5: =+ROUND(D5+E5,1) -> 551.1 | G5: =+ROUND(G4-E5,1) -> 24856.6 | I5: SALDO | J5: 5560.8
A6: 2 | B6: 45686 | D6: =+ROUND(G5*0.01,1) -> 248.6 | E6: =ROUNDUP($C$4/84,1) -> 299.5 | F6: =+ROUND(D6+E6,1) -> 548.1 | G6: =+ROUND(G5-E6,1) -> 24557.1 | I6: PRESTAMO | J6: 19595.3
A7: 3 | B7: 45716 | D7: =+ROUND(G6*0.01,1) -> 245.6 | E7: =ROUNDUP($C$4/84,1) -> 299.5 | F7: =+ROUND(D7+E7,1) -> 545.1 | G7: =+ROUND(G6-E7,1) -> 24257.6 | I7: TOTAL | J7: =+SUM(J5:J6) -> 25156.1
A8: 4 | B8: 45745 | D8: =+ROUND(G7*0.01,1) -> 242.6 | E8: =ROUNDUP($C$4/84,1) -> 299.5 | F8: =+ROUND(D8+E8,1) -> 542.1 | G8: =+ROUND(G7-E8,1) -> 23958.1
A9: 5 | B9: 45776 | D9: =+ROUND(G8*0.01,1) -> 239.6 | E9: =ROUNDUP($C$4/84,1) -> 299.5 | F9: =+ROUND(D9+E9,1) -> 539.1 | G9: =+ROUND(G8-E9,1) -> 23658.6
A10: 6 | B10: 45806 | D10: =+ROUND(G9*0.01,1) -> 236.6 | E10: =ROUNDUP($C$4/84,1) -> 299.5 | F10: =+ROUND(D10+E10,1) -> 536.1 | G10: =+ROUND(G9-E10,1) -> 23359.1
A11: 7 | B11: 45837 | D11: =+ROUND(G10*0.01,1) -> 233.6 | E11: =ROUNDUP($C$4/84,1) -> 299.5 | F11: =+ROUND(D11+E11,1) -> 533.1 | G11: =+ROUND(G10-E11,1) -> 23059.6
A12: 8 | B12: 45867 | D12: =+ROUND(G11*0.01,1) -> 230.6 | E12: =ROUNDUP($C$4/84,1) -> 299.5 | F12: =+ROUND(D12+E12,1) -> 530.1 | G12: =+ROUND(G11-E12,1) -> 22760.1
A13: 9 | B13: 45898 | D13: =+ROUND(G12*0.01,1) -> 227.6 | E13: =ROUNDUP($C$4/84,1) -> 299.5 | F13: =+ROUND(D13+E13,1) -> 527.1 | G13: =+ROUND(G12-E13,1) -> 22460.6
A14: 10 | B14: 45929 | D14: =+ROUND(G13*0.01,1) -> 224.6 | E14: =ROUNDUP($C$4/84,1) -> 299.5 | F14: =+ROUND(D14+E14,1) -> 524.1 | G14: =+ROUND(G13-E14,1) -> 22161.1
A15: 11 | B15: 45959 | D15: =+ROUND(G14*0.01,1) -> 221.6 | E15: =ROUNDUP($C$4/84,1) -> 299.5 | F15: =+ROUND(D15+E15,1) -> 521.1 | G15: =+ROUND(G14-E15,1) -> 21861.6
A16: 12 | B16: 45990 | D16: =+ROUND(G15*0.01,1) -> 218.6 | E16: =ROUNDUP($C$4/84,1) -> 299.5 | F16: =+ROUND(D16+E16,1) -> 518.1 | G16: =+ROUND(G15-E16,1) -> 21562.1
A17: 13 | B17: 46020 | D17: =+ROUND(G16*0.01,1) -> 215.6 | E17: =ROUNDUP($C$4/84,1) -> 299.5 | F17: =+ROUND(D17+E17,1) -> 515.1 | G17: =+ROUND(G16-E17,1) -> 21262.6
A18: 14 | B18: 46051 | D18: =+ROUND(G17*0.01,1) -> 212.6 | E18: =ROUNDUP($C$4/84,1) -> 299.5 | F18: =+ROUND(D18+E18,1) -> 512.1 | G18: =+ROUND(G17-E18,1) -> 20963.1
A19: 15 | B19: 46081 | D19: =+ROUND(G18*0.01,1) -> 209.6 | E19: =ROUNDUP($C$4/84,1) -> 299.5 | F19: =+ROUND(D19+E19,1) -> 509.1 | G19: =+ROUND(G18-E19,1) -> 20663.6
... A87: 83 | B87: 48150 | D87: =+ROUND(G86*0.01,1) -> 6 | E87: =ROUNDUP($C$4/84,1) -> 299.5 | F87: =+ROUND(D87+E87,1) -> 305.5 | G87: =+ROUND(G86-E87,1) -> 297.6
A88: 84 | B88: 48181 | D88: =+ROUND(G87*0.01,1) -> 3 | E88: =ROUNDUP($C$4/84,1)-1.9 -> 297.6 | F88: =+ROUND(D88+E88,1) -> 300.6 | G88: =+ROUND(G87-E88,1) -> 0
A89: TOTAL | D89: =+SUM(D5:D88) -> 10690.8 | E89: =+SUM(E5:E88) -> 25156.1 | F89: =+SUM(F5:F88) -> 35846.9

Sheet 2
A1: SOCIA: ALVAREZ DÍAZ, RENÉ
A2: FEBRERO 2026 - PRÉSTAMO
A3: PLAZO | B3: FECHA | C3: PRÉSTAMO S/. | D3: INTERES | E3: ABONO DE CAPITAL | F3: CUOTA | G3: SALDO
A4: 0 | B4: 46081 | C4: =+J7 -> 29153.1 | D4: 0.01 | G4: =+C4 -> 29153.1
A5: 1 | B5: 46110 | D5: =+ROUND(G4*0.01,1) -> 291.5 | E5: =ROUNDUP($C$4/60,1) -> 485.9 | F5: =+ROUND(D5+E5,1) -> 777.4 | G5: =+ROUND(G4-E5,1) -> 28667.2 | I5: SALDO | J5: 0
A6: 2 | B6: 46141 | D6: =+ROUND(G5*0.01,1) -> 286.7 | E6: =ROUNDUP($C$4/60,1) -> 485.9 | F6: =+ROUND(D6+E6,1) -> 772.6 | G6: =+ROUND(G5-E6,1) -> 28181.3 | I6: PRESTAMO | J6: 29153.1
A7: 3 | B7: 46171 | D7: =+ROUND(G6*0.01,1) -> 281.8 | E7: =ROUNDUP($C$4/60,1) -> 485.9 | F7: =+ROUND(D7+E7,1) -> 767.7 | G7: =+ROUND(G6-E7,1) -> 27695.4 | I7: TOTAL | J7: =+SUM(J5:J6) -> 29153.1
A8: 4 | B8: 46202 | D8: =+ROUND(G7*0.01,1) -> 277 | E8: =ROUNDUP($C$4/60,1) -> 485.9 | F8: =+ROUND(D8+E8,1) -> 762.9 | G8: =+ROUND(G7-E8,1) -> 27209.5
A9: 5 | B9: 46232 | D9: =+ROUND(G8*0.01,1) -> 272.1 | E9: =ROUNDUP($C$4/60,1) -> 485.9 | F9: =+ROUND(D9+E9,1) -> 758 | G9: =+ROUND(G8-E9,1) -> 26723.6
A10: 6 | B10: 46263 | D10: =+ROUND(G9*0.01,1) -> 267.2 | E10: =ROUNDUP($C$4/60,1) -> 485.9 | F10: =+ROUND(D10+E10,1) -> 753.1 | G10: =+ROUND(G9-E10,1) -> 26237.7
A11: 7 | B11: 46294 | D11: =+ROUND(G10*0.01,1) -> 262.4 | E11: =ROUNDUP($C$4/60,1) -> 485.9 | F11: =+ROUND(D11+E11,1) -> 748.3 | G11: =+ROUND(G10-E11,1) -> 25751.8
A12: 8 | B12: 46324 | D12: =+ROUND(G11*0.01,1) -> 257.5 | E12: =ROUNDUP($C$4/60,1) -> 485.9 | F12: =+ROUND(D12+E12,1) -> 743.4 | G12: =+ROUND(G11-E12,1) -> 25265.9
A13: 9 | B13: 46355 | D13: =+ROUND(G12*0.01,1) -> 252.7 | E13: =ROUNDUP($C$4/60,1) -> 485.9 | F13: =+ROUND(D13+E13,1) -> 738.6 | G13: =+ROUND(G12-E13,1) -> 24780
A14: 10 | B14: 46385 | D14: =+ROUND(G13*0.01,1) -> 247.8 | E14: =ROUNDUP($C$4/60,1) -> 485.9 | F14: =+ROUND(D14+E14,1) -> 733.7 | G14: =+ROUND(G13-E14,1) -> 24294.1
A15: 11 | B15: 46416 | D15: =+ROUND(G14*0.01,1) -> 242.9 | E15: =ROUNDUP($C$4/60,1) -> 485.9 | F15: =+ROUND(D15+E15,1) -> 728.8 | G15: =+ROUND(G14-E15,1) -> 23808.2
A16: 12 | B16: 46446 | D16: =+ROUND(G15*0.01,1) -> 238.1 | E16: =ROUNDUP($C$4/60,1) -> 485.9 | F16: =+ROUND(D16+E16,1) -> 724 | G16: =+ROUND(G15-E16,1) -> 23322.3
A17: 13 | B17: 46475 | D17: =+ROUND(G16*0.01,1) -> 233.2 | E17: =ROUNDUP($C$4/60,1) -> 485.9 | F17: =+ROUND(D17+E17,1) -> 719.1 | G17: =+ROUND(G16-E17,1) -> 22836.4
A18: 14 | B18: 46506 | D18: =+ROUND(G17*0.01,1) -> 228.4 | E18: =ROUNDUP($C$4/60,1) -> 485.9 | F18: =+ROUND(D18+E18,1) -> 714.3 | G18: =+ROUND(G17-E18,1) -> 22350.5
A19: 15 | B19: 46536 | D19: =+ROUND(G18*0.01,1) -> 223.5 | E19: =ROUNDUP($C$4/60,1) -> 485.9 | F19: =+ROUND(D19+E19,1) -> 709.4 | G19: =+ROUND(G18-E19,1) -> 21864.6
... A63: 59 | B63: 47877 | D63: =+ROUND(G62*0.01,1) -> 9.7 | E63: =ROUNDUP($C$4/60,1) -> 485.9 | F63: =+ROUND(D63+E63,1) -> 495.6 | G63: =+ROUND(G62-E63,1) -> 485
A64: 60 | B64: 47907 | D64: =+ROUND(G63*0.01,1) -> 4.9 | E64: =ROUNDUP($C$4/60,1)-0.9 -> 485 | F64: =+ROUND(D64+E64,1) -> 489.9 | G64: =+ROUND(G63-E64,1) -> 0
A65: TOTAL | D65: =+SUM(D5:D64) -> 8891.5 | E65: =+SUM(E5:E64) -> 29153.1 | F65: =+SUM(F5:F64) -> 38044.6

Sheet 3
A1: SOCIA: MAGDA ARAUJO SANCHEZ
A2: MAYO 2025 - PRÉSTAMO
A3: PLAZO | B3: FECHA | C3: PRÉSTAMO S/. | D3: INTERES | E3: ABONO DE CAPITAL | F3: CUOTA | G3: SALDO
A4: 0 | B4: 45806 | C4: =+J7 -> 43268.3 | D4: 0.01 | G4: =+C4 -> 43268.3
A5: 1 | B5: 45837 | D5: =+ROUND(G4*0.01,1) -> 432.7 | E5: =ROUNDUP(C4/84,1) -> 515.1 | F5: =+ROUND(D5+E5,1) -> 947.8 | G5: =+ROUND(G4-E5,1) -> 42753.2 | I5: SALDO | J5: 40268.3
A6: 2 | B6: 45867 | D6: =+ROUND(G5*0.01,1) -> 427.5 | E6: =ROUNDUP($C$4/84,1) -> 515.1 | F6: =+ROUND(D6+E6,1) -> 942.6 | G6: =+ROUND(G5-E6,1) -> 42238.1 | I6: PRESTAMO | J6: 3000
A7: 3 | B7: 45898 | D7: =+ROUND(G6*0.01,1) -> 422.4 | E7: =ROUNDUP($C$4/84,1) -> 515.1 | F7: =+ROUND(D7+E7,1) -> 937.5 | G7: =+ROUND(G6-E7,1) -> 41723 | I7: TOTAL | J7: =+SUM(J5:J6) -> 43268.3
A8: 4 | B8: 45929 | D8: =+ROUND(G7*0.01,1) -> 417.2 | E8: =ROUNDUP($C$4/84,1) -> 515.1 | F8: =+ROUND(D8+E8,1) -> 932.3 | G8: =+ROUND(G7-E8,1) -> 41207.9
A9: 5 | B9: 45959 | D9: =+ROUND(G8*0.01,1) -> 412.1 | E9: =ROUNDUP($C$4/84,1) -> 515.1 | F9: =+ROUND(D9+E9,1) -> 927.2 | G9: =+ROUND(G8-E9,1) -> 40692.8
A10: 6 | B10: 45990 | D10: =+ROUND(G9*0.01,1) -> 406.9 | E10: =ROUNDUP($C$4/84,1) -> 515.1 | F10: =+ROUND(D10+E10,1) -> 922 | G10: =+ROUND(G9-E10,1) -> 40177.7
A11: 7 | B11: 46020 | D11: =+ROUND(G10*0.01,1) -> 401.8 | E11: =ROUNDUP($C$4/84,1) -> 515.1 | F11: =+ROUND(D11+E11,1) -> 916.9 | G11: =+ROUND(G10-E11,1) -> 39662.6
A12: 8 | B12: 46051 | D12: =+ROUND(G11*0.01,1) -> 396.6 | E12: =ROUNDUP($C$4/84,1) -> 515.1 | F12: =+ROUND(D12+E12,1) -> 911.7 | G12: =+ROUND(G11-E12,1) -> 39147.5
A13: 9 | B13: 46081 | D13: =+ROUND(G12*0.01,1) -> 391.5 | E13: =ROUNDUP($C$4/84,1) -> 515.1 | F13: =+ROUND(D13+E13,1) -> 906.6 | G13: =+ROUND(G12-E13,1) -> 38632.4
A14: 10 | B14: 46110 | D14: =+ROUND(G13*0.01,1) -> 386.3 | E14: =ROUNDUP($C$4/84,1) -> 515.1 | F14: =+ROUND(D14+E14,1) -> 901.4 | G14: =+ROUND(G13-E14,1) -> 38117.3
A15: 11 | B15: 46141 | D15: =+ROUND(G14*0.01,1) -> 381.2 | E15: =ROUNDUP($C$4/84,1) -> 515.1 | F15: =+ROUND(D15+E15,1) -> 896.3 | G15: =+ROUND(G14-E15,1) -> 37602.2
A16: 12 | B16: 46171 | D16: =+ROUND(G15*0.01,1) -> 376 | E16: =ROUNDUP($C$4/84,1) -> 515.1 | F16: =+ROUND(D16+E16,1) -> 891.1 | G16: =+ROUND(G15-E16,1) -> 37087.1
A17: 13 | B17: 46202 | D17: =+ROUND(G16*0.01,1) -> 370.9 | E17: =ROUNDUP($C$4/84,1) -> 515.1 | F17: =+ROUND(D17+E17,1) -> 886 | G17: =+ROUND(G16-E17,1) -> 36572
A18: 14 | B18: 46232 | D18: =+ROUND(G17*0.01,1) -> 365.7 | E18: =ROUNDUP($C$4/84,1) -> 515.1 | F18: =+ROUND(D18+E18,1) -> 880.8 | G18: =+ROUND(G17-E18,1) -> 36056.9
A19: 15 | B19: 46263 | D19: =+ROUND(G18*0.01,1) -> 360.6 | E19: =ROUNDUP($C$4/84,1) -> 515.1 | F19: =+ROUND(D19+E19,1) -> 875.7 | G19: =+ROUND(G18-E19,1) -> 35541.8
... A87: 83 | B87: 48333 | D87: =+ROUND(G86*0.01,1) -> 10.3 | E87: =ROUNDUP($C$4/84,1) -> 515.1 | F87: =+ROUND(D87+E87,1) -> 525.4 | G87: =+ROUND(G86-E87,1) -> 515
A88: 84 | B88: 48363 | D88: =+ROUND(G87*0.01,1) -> 5.2 | E88: 515 | F88: =+ROUND(D88+E88,1) -> 520.2 | G88: =+ROUND(G87-E88,1) -> 0
A89: TOTAL | D89: =+SUM(D5:D88) -> 18389.3 | E89: =+SUM(E5:E88) -> 43268.3 | F89: =+SUM(F5:F88) -> 61657.6

Sheet 4
A1: SOCIO: LUIS BARRANTES ROJAS
A2: ABRIL 2023 - PRÉSTAMO
A3: PLAZO | B3: FECHA | C3: PRÉSTAMO S/. | D3: INTERES | E3: ABONO DE CAPITAL | F3: CUOTA | G3: SALDO
A4: 0 | B4: 45045 | C4: =+J7 -> 44154.4 | D4: 0.01 | G4: =+C4 -> 44154.4
A5: 1 | B5: 45075 | D5: =+ROUND(G4*0.01,1) -> 441.5 | E5: =ROUNDUP(C4/72,1) -> 613.3 | F5: =+ROUND(D5+E5,1) -> 1054.8 | G5: =+ROUND(G4-E5,1) -> 43541.1 | I5: SALDO | J5: 44154.4
A6: 2 | B6: 45106 | D6: =+ROUND(G5*0.01,1) -> 435.4 | E6: =ROUNDUP($C$4/72,1) -> 613.3 | F6: =+ROUND(D6+E6,1) -> 1048.7 | G6: =+ROUND(G5-E6,1) -> 42927.8 | I6: PRESTAMO | J6: 0
A7: 3 | B7: 45136 | D7: =+ROUND(G6*0.01,1) -> 429.3 | E7: =ROUNDUP($C$4/72,1) -> 613.3 | F7: =+ROUND(D7+E7,1) -> 1042.6 | G7: =+ROUND(G6-E7,1) -> 42314.5 | I7: TOTAL | J7: =+SUM(J5:J6) -> 44154.4
A8: 4 | B8: 45167 | D8: =+ROUND(G7*0.01,1) -> 423.1 | E8: =ROUNDUP($C$4/72,1) -> 613.3 | F8: =+ROUND(D8+E8,1) -> 1036.4 | G8: =+ROUND(G7-E8,1) -> 41701.2
A9: 5 | B9: 45198 | D9: =+ROUND(G8*0.01,1) -> 417 | E9: =ROUNDUP($C$4/72,1) -> 613.3 | F9: =+ROUND(D9+E9,1) -> 1030.3 | G9: =+ROUND(G8-E9,1) -> 41087.9
A10: 6 | B10: 45228 | D10: =+ROUND(G9*0.01,1) -> 410.9 | E10: =ROUNDUP($C$4/72,1) -> 613.3 | F10: =+ROUND(D10+E10,1) -> 1024.2 | G10: =+ROUND(G9-E10,1) -> 40474.6
A11: 7 | B11: 45259 | D11: =+ROUND(G10*0.01,1) -> 404.7 | E11: =ROUNDUP($C$4/72,1) -> 613.3 | F11: =+ROUND(D11+E11,1) -> 1018 | G11: =+ROUND(G10-E11,1) -> 39861.3
A12: 8 | B12: 45289 | D12: =+ROUND(G11*0.01,1) -> 398.6 | E12: =ROUNDUP($C$4/72,1) -> 613.3 | F12: =+ROUND(D12+E12,1) -> 1011.9 | G12: =+ROUND(G11-E12,1) -> 39248
A13: 9 | B13: 45320 | D13: =+ROUND(G12*0.01,1) -> 392.5 | E13: =ROUNDUP($C$4/72,1) -> 613.3 | F13: =+ROUND(D13+E13,1) -> 1005.8 | G13: =+ROUND(G12-E13,1) -> 38634.7
A14: 10 | B14: 45351 | D14: =+ROUND(G13*0.01,1) -> 386.3 | E14: =ROUNDUP($C$4/72,1) -> 613.3 | F14: =+ROUND(D14+E14,1) -> 999.6 | G14: =+ROUND(G13-E14,1) -> 38021.4
A15: 11 | B15: 45380 | D15: =+ROUND(G14*0.01,1) -> 380.2 | E15: =ROUNDUP($C$4/72,1) -> 613.3 | F15: =+ROUND(D15+E15,1) -> 993.5 | G15: =+ROUND(G14-E15,1) -> 37408.1
A16: 12 | B16: 45411 | D16: =+ROUND(G15*0.01,1) -> 374.1 | E16: =ROUNDUP($C$4/72,1) -> 613.3 | F16: =+ROUND(D16+E16,1) -> 987.4 | G16: =+ROUND(G15-E16,1) -> 36794.8
A17: 13 | B17: 45441 | D17: =+ROUND(G16*0.01,1) -> 367.9 | E17: =ROUNDUP($C$4/72,1) -> 613.3 | F17: =+ROUND(D17+E17,1) -> 981.2 | G17: =+ROUND(G16-E17,1) -> 36181.5
A18: 14 | B18: 45472 | D18: =+ROUND(G17*0.01,1) -> 361.8 | E18: =ROUNDUP($C$4/72,1) -> 613.3 | F18: =+ROUND(D18+E18,1) -> 975.1 | G18: =+ROUND(G17-E18,1) -> 35568.2
A19: 15 | B19: 45502 | D19: =+ROUND(G18*0.01,1) -> 355.7 | E19: =ROUNDUP($C$4/72,1) -> 613.3 | F19: =+ROUND(D19+E19,1) -> 969 | G19: =+ROUND(G18-E19,1) -> 34954.9
... A44: 40 | B44: 46263 | D44: =+ROUND(G43*0.01,1) -> 202.4 | E44: =ROUNDUP($C$4/72,1) -> 613.3 | F44: =+ROUND(D44+E44,1) -> 815.7 | G44: =+ROUND(G43-E44,1) -> 19622.4
A45: 41 | B45: 46294 | D45: =+ROUND(G44*0.01,1) -> 196.2 | E45: =ROUNDDOWN($C$4/72,1) -> 613.2 | F45: =+ROUND(D45+E45,1) -> 809.4 | G45: =+ROUND(G44-E45,1) -> 19009.2
A46: 42 | B46: 46324 | D46: =+ROUND(G45*0.01,1) -> 190.1 | E46: =ROUNDDOWN($C$4/72,1) -> 613.2 | F46: =+ROUND(D46+E46,1) -> 803.3 | G46: =+ROUND(G45-E46,1) -> 18396
A47: 43 | B47: 46355 | D47: =+ROUND(G46*0.01,1) -> 184 | E47: =ROUNDDOWN($C$4/72,1) -> 613.2 | F47: =+ROUND(D47+E47,1) -> 797.2 | G47: =+ROUND(G46-E47,1) -> 17782.8
A48: 44 | B48: 46385 | D48: =+ROUND(G47*0.01,1) -> 177.8 | E48: =ROUNDDOWN($C$4/72,1) -> 613.2 | F48: =+ROUND(D48+E48,1) -> 791 | G48: =+ROUND(G47-E48,1) -> 17169.6
A49: 45 | B49: 46416 | D49: =+ROUND(G48*0.01,1) -> 171.7 | E49: =ROUNDDOWN($C$4/72,1) -> 613.2 | F49: =+ROUND(D49+E49,1) -> 784.9 | G49: =+ROUND(G48-E49,1) -> 16556.4
A50: 46 | B50: 46446 | D50: =+ROUND(G49*0.01,1) -> 165.6 | E50: =ROUNDDOWN($C$4/72,1) -> 613.2 | F50: =+ROUND(D50+E50,1) -> 778.8 | G50: =+ROUND(G49-E50,1) -> 15943.2
A51: 47 | B51: 46475 | D51: =+ROUND(G50*0.01,1) -> 159.4 | E51: =ROUNDDOWN($C$4/72,1) -> 613.2 | F51: =+ROUND(D51+E51,1) -> 772.6 | G51: =+ROUND(G50-E51,1) -> 15330
A52: 48 | B52: 46506 | D52: =+ROUND(G51*0.01,1) -> 153.3 | E52: =ROUNDDOWN($C$4/72,1) -> 613.2 | F52: =+ROUND(D52+E52,1) -> 766.5 | G52: =+ROUND(G51-E52,1) -> 14716.8
A53: 49 | B53: 46536 | D53: =+ROUND(G52*0.01,1) -> 147.2 | E53: =ROUNDDOWN($C$4/72,1) -> 613.2 | F53: =+ROUND(D53+E53,1) -> 760.4 | G53: =+ROUND(G52-E53,1) -> 14103.6
A54: 50 | B54: 46567 | D54: =+ROUND(G53*0.01,1) -> 141 | E54: =ROUNDDOWN($C$4/72,1) -> 613.2 | F54: =+ROUND(D54+E54,1) -> 754.2 | G54: =+ROUND(G53-E54,1) -> 13490.4
A55: 51 | B55: 46597 | D55: =+ROUND(G54*0.01,1) -> 134.9 | E55: =ROUNDDOWN($C$4/72,1) -> 613.2 | F55: =+ROUND(D55+E55,1) -> 748.1 | G55: =+ROUND(G54-E55,1) -> 12877.2
A56: 52 | B56: 46628 | D56: =+ROUND(G55*0.01,1) -> 128.8 | E56: =ROUNDDOWN($C$4/72,1) -> 613.2 | F56: =+ROUND(D56+E56,1) -> 742 | G56: =+ROUND(G55-E56,1) -> 12264
... A76: 72 | B76: 47237 | D76: =+ROUND(G75*0.01,1) -> 6.1 | E76: =ROUNDDOWN($C$4/72,1) -> 613.2 | F76: =+ROUND(D76+E76,1) -> 619.3 | G76: =+ROUND(G75-E76,1) -> 0
A77: TOTAL | D77: =+SUM(D5:D76) -> 16115.8 | E77: =+SUM(E5:E76) -> 44154.4 | F77: =+SUM(F5:F76) -> 60270.2

Sheet 5
A1: SOCIA: BAZAN VASQUEZ, MIRTHA LUSNILDA
A2: AGOSTO 2025 - PRÉSTAMO
A3: PLAZO | B3: FECHA | C3: PRÉSTAMO S/. | D3: INTERES | E3: ABONO DE CAPITAL | F3: CUOTA | G3: SALDO
A4: 0 | B4: 45898 | C4: =+J7 -> 31193.2 | D4: 0.01 | G4: =+C4 -> 31193.2
A5: 1 | B5: 45929 | D5: =+ROUND(G4*0.01,1) -> 311.9 | E5: =ROUNDUP($C$4/60,1) -> 519.9 | F5: =+ROUND(D5+E5,1) -> 831.8 | G5: =+ROUND(G4-E5,1) -> 30673.3 | I5: SALDO | J5: 11193.2
A6: 2 | B6: 45959 | D6: =+ROUND(G5*0.01,1) -> 306.7 | E6: =ROUNDUP($C$4/60,1) -> 519.9 | F6: =+ROUND(D6+E6,1) -> 826.6 | G6: =+ROUND(G5-E6,1) -> 30153.4 | I6: PRESTAMO | J6: 20000
A7: 3 | B7: 45990 | D7: =+ROUND(G6*0.01,1) -> 301.5 | E7: =ROUNDUP($C$4/60,1) -> 519.9 | F7: =+ROUND(D7+E7,1) -> 821.4 | G7: =+ROUND(G6-E7,1) -> 29633.5 | I7: TOTAL | J7: =+SUM(J5:J6) -> 31193.2
A8: 4 | B8: 46020 | D8: =+ROUND(G7*0.01,1) -> 296.3 | E8: =ROUNDUP($C$4/60,1) -> 519.9 | F8: =+ROUND(D8+E8,1) -> 816.2 | G8: =+ROUND(G7-E8,1) -> 29113.6
A9: 5 | B9: 46051 | D9: =+ROUND(G8*0.01,1) -> 291.1 | E9: =ROUNDUP($C$4/60,1) -> 519.9 | F9: =+ROUND(D9+E9,1) -> 811 | G9: =+ROUND(G8-E9,1) -> 28593.7
A10: 6 | B10: 46081 | D10: =+ROUND(G9*0.01,1) -> 285.9 | E10: =ROUNDUP($C$4/60,1) -> 519.9 | F10: =+ROUND(D10+E10,1) -> 805.8 | G10: =+ROUND(G9-E10,1) -> 28073.8
A11: 7 | B11: 46110 | D11: =+ROUND(G10*0.01,1) -> 280.7 | E11: =ROUNDUP($C$4/60,1) -> 519.9 | F11: =+ROUND(D11+E11,1) -> 800.6 | G11: =+ROUND(G10-E11,1) -> 27553.9
A12: 8 | B12: 46141 | D12: =+ROUND(G11*0.01,1) -> 275.5 | E12: =ROUNDUP($C$4/60,1) -> 519.9 | F12: =+ROUND(D12+E12,1) -> 795.4 | G12: =+ROUND(G11-E12,1) -> 27034
A13: 9 | B13: 46171 | D13: =+ROUND(G12*0.01,1) -> 270.3 | E13: =ROUNDUP($C$4/60,1) -> 519.9 | F13: =+ROUND(D13+E13,1) -> 790.2 | G13: =+ROUND(G12-E13,1) -> 26514.1
A14: 10 | B14: 46202 | D14: =+ROUND(G13*0.01,1) -> 265.1 | E14: =ROUNDUP($C$4/60,1) -> 519.9 | F14: =+ROUND(D14+E14,1) -> 785 | G14: =+ROUND(G13-E14,1) -> 25994.2
A15: 11 | B15: 46232 | D15: =+ROUND(G14*0.01,1) -> 259.9 | E15: =ROUNDUP($C$4/60,1) -> 519.9 | F15: =+ROUND(D15+E15,1) -> 779.8 | G15: =+ROUND(G14-E15,1) -> 25474.3
A16: 12 | B16: 46263 | D16: =+ROUND(G15*0.01,1) -> 254.7 | E16: =ROUNDUP($C$4/60,1) -> 519.9 | F16: =+ROUND(D16+E16,1) -> 774.6 | G16: =+ROUND(G15-E16,1) -> 24954.4
A17: 13 | B17: 46294 | D17: =+ROUND(G16*0.01,1) -> 249.5 | E17: =ROUNDUP($C$4/60,1) -> 519.9 | F17: =+ROUND(D17+E17,1) -> 769.4 | G17: =+ROUND(G16-E17,1) -> 24434.5
A18: 14 | B18: 46324 | D18: =+ROUND(G17*0.01,1) -> 244.3 | E18: =ROUNDUP($C$4/60,1) -> 519.9 | F18: =+ROUND(D18+E18,1) -> 764.2 | G18: =+ROUND(G17-E18,1) -> 23914.6
A19: 15 | B19: 46355 | D19: =+ROUND(G18*0.01,1) -> 239.1 | E19: =ROUNDUP($C$4/60,1) -> 519.9 | F19: =+ROUND(D19+E19,1) -> 759 | G19: =+ROUND(G18-E19,1) -> 23394.7
... A63: 59 | B63: 47693 | D63: =+ROUND(G62*0.01,1) -> 10.4 | E63: =ROUNDUP($C$4/60,1) -> 519.9 | F63: =+ROUND(D63+E63,1) -> 530.3 | G63: =+ROUND(G62-E63,1) -> 519.1
A64: 60 | B64: 47724 | D64: =+ROUND(G63*0.01,1) -> 5.2 | E64: =ROUNDUP($C$4/60,1)-0.8 -> 519.1 | F64: =+ROUND(D64+E64,1) -> 524.3 | G64: =+ROUND(G63-E64,1) -> 0
A65: TOTAL | D65: =+SUM(D5:D64) -> 9514.2 | E65: =+SUM(E5:E64) -> 31193.2 | F65: =+SUM(F5:F64) -> 40707.4

Sheet 6
A1: SOCIO: JORGE CABANILLAS IZQUIERDO
A2: MAYO 2025 - PRÉSTAMO
A3: PLAZO | B3: FECHA | C3: PRÉSTAMO S/. | D3: INTERES | E3: ABONO DE CAPITAL | F3: CUOTA | G3: SALDO
A4: 0 | B4: 45806 | C4: =+J7 -> 35401.9 | D4: 0.01 | G4: =+C4 -> 35401.9
A5: 1 | B5: 45837 | D5: =+ROUND(G4*0.01,1) -> 354 | E5: =ROUNDUP(C4/84,1) -> 421.5 | F5: =+ROUND(D5+E5,1) -> 775.5 | G5: =+ROUND(G4-E5,1) -> 34980.4 | I5: SALDO | J5: 25818.6
A6: 2 | B6: 45867 | D6: =+ROUND(G5*0.01,1) -> 349.8 | E6: =ROUNDUP($C$4/84,1) -> 421.5 | F6: =+ROUND(D6+E6,1) -> 771.3 | G6: =+ROUND(G5-E6,1) -> 34558.9 | I6: PRESTAMO | J6: 9583.3
A7: 3 | B7: 45898 | D7: =+ROUND(G6*0.01,1) -> 345.6 | E7: =ROUNDUP($C$4/84,1) -> 421.5 | F7: =+ROUND(D7+E7,1) -> 767.1 | G7: =+ROUND(G6-E7,1) -> 34137.4 | I7: TOTAL | J7: =+SUM(J5:J6) -> 35401.9
A8: 4 | B8: 45929 | D8: =+ROUND(G7*0.01,1) -> 341.4 | E8: =ROUNDUP($C$4/84,1) -> 421.5 | F8: =+ROUND(D8+E8,1) -> 762.9 | G8: =+ROUND(G7-E8,1) -> 33715.9
A9: 5 | B9: 45959 | D9: =+ROUND(G8*0.01,1) -> 337.2 | E9: =ROUNDUP($C$4/84,1) -> 421.5 | F9: =+ROUND(D9+E9,1) -> 758.7 | G9: =+ROUND(G8-E9,1) -> 33294.4
A10: 6 | B10: 45990 | D10: =+ROUND(G9*0.01,1) -> 332.9 | E10: =ROUNDUP($C$4/84,1) -> 421.5 | F10: =+ROUND(D10+E10,1) -> 754.4 | G10: =+ROUND(G9-E10,1) -> 32872.9
A11: 7 | B11: 46020 | D11: =+ROUND(G10*0.01,1) -> 328.7 | E11: =ROUNDUP($C$4/84,1) -> 421.5 | F11: =+ROUND(D11+E11,1) -> 750.2 | G11: =+ROUND(G10-E11,1) -> 32451.4
A12: 8 | B12: 46051 | D12: =+ROUND(G11*0.01,1) -> 324.5 | E12: =ROUNDUP($C$4/84,1) -> 421.5 | F12: =+ROUND(D12+E12,1) -> 746 | G12: =+ROUND(G11-E12,1) -> 32029.9
A13: 9 | B13: 46081 | D13: =+ROUND(G12*0.01,1) -> 320.3 | E13: =ROUNDUP($C$4/84,1) -> 421.5 | F13: =+ROUND(D13+E13,1) -> 741.8 | G13: =+ROUND(G12-E13,1) -> 31608.4
A14: 10 | B14: 46110 | D14: =+ROUND(G13*0.01,1) -> 316.1 | E14: =ROUNDUP($C$4/84,1) -> 421.5 | F14: =+ROUND(D14+E14,1) -> 737.6 | G14: =+ROUND(G13-E14,1) -> 31186.9
A15: 11 | B15: 46141 | D15: =+ROUND(G14*0.01,1) -> 311.9 | E15: =ROUNDUP($C$4/84,1) -> 421.5 | F15: =+ROUND(D15+E15,1) -> 733.4 | G15: =+ROUND(G14-E15,1) -> 30765.4
A16: 12 | B16: 46171 | D16: =+ROUND(G15*0.01,1) -> 307.7 | E16: =ROUNDUP($C$4/84,1) -> 421.5 | F16: =+ROUND(D16+E16,1) -> 729.2 | G16: =+ROUND(G15-E16,1) -> 30343.9
A17: 13 | B17: 46202 | D17: =+ROUND(G16*0.01,1) -> 303.4 | E17: =ROUNDUP($C$4/84,1) -> 421.5 | F17: =+ROUND(D17+E17,1) -> 724.9 | G17: =+ROUND(G16-E17,1) -> 29922.4
A18: 14 | B18: 46232 | D18: =+ROUND(G17*0.01,1) -> 299.2 | E18: =ROUNDUP($C$4/84,1) -> 421.5 | F18: =+ROUND(D18+E18,1) -> 720.7 | G18: =+ROUND(G17-E18,1) -> 29500.9
A19: 15 | B19: 46263 | D19: =+ROUND(G18*0.01,1) -> 295 | E19: =ROUNDUP($C$4/84,1) -> 421.5 | F19: =+ROUND(D19+E19,1) -> 716.5 | G19: =+ROUND(G18-E19,1) -> 29079.4
... A87: 83 | B87: 48333 | D87: =+ROUND(G86*0.01,1) -> 8.4 | E87: =ROUNDUP($C$4/84,1) -> 421.5 | F87: =+ROUND(D87+E87,1) -> 429.9 | G87: =+ROUND(G86-E87,1) -> 417.4
A88: 84 | B88: 48363 | D88: =+ROUND(G87*0.01,1) -> 4.2 | E88: =ROUNDUP($C$4/84,1)-4.1 -> 417.4 | F88: =+ROUND(D88+E88,1) -> 421.6 | G88: =+ROUND(G87-E88,1) -> 0
A89: TOTAL | D89: =+SUM(D5:D88) -> 15044 | E89: =+SUM(E5:E88) -> 35401.9 | F89: =+SUM(F5:F88) -> 50445.9

Sheet 7
A1: SOCIO: JORGE ARTURO CHAVEZ ALVAREZ
A2: JULIO 2025 - PRÉSTAMO
A3: PLAZO | B3: FECHA | C3: PRÉSTAMO S/. | D3: INTERES | E3: ABONO DE CAPITAL | F3: CUOTA | G3: SALDO
A4: 0 | B4: 45867 | C4: =+J7 -> 25395.8 | D4: 0.01 | G4: =+C4 -> 25395.8
A5: 1 | B5: 45898 | D5: =+ROUND(G4*0.01,1) -> 254 | E5: =ROUNDDOWN(C4/84,1) -> 302.3 | F5: =+ROUND(D5+E5,1) -> 556.3 | G5: =+ROUND(G4-E5,1) -> 25093.5 | I5: SALDO | J5: 26995.8
A6: 2 | B6: 45929 | D6: =+ROUND(G5*0.01,1) -> 250.9 | E6: =ROUNDDOWN($C$4/84,1) -> 302.3 | F6: =+ROUND(D6+E6,1) -> 553.2 | G6: =+ROUND(G5-E6,1) -> 24791.2 | I6: DEVOLUCIÓN | J6: -1600
A7: 3 | B7: 45959 | D7: =+ROUND(G6*0.01,1) -> 247.9 | E7: =ROUNDDOWN($C$4/84,1) -> 302.3 | F7: =+ROUND(D7+E7,1) -> 550.2 | G7: =+ROUND(G6-E7,1) -> 24488.9 | I7: TOTAL | J7: =+SUM(J5:J6) -> 25395.8
A8: 4 | B8: 45990 | D8: =+ROUND(G7*0.01,1) -> 244.9 | E8: =ROUNDDOWN($C$4/84,1) -> 302.3 | F8: =+ROUND(D8+E8,1) -> 547.2 | G8: =+ROUND(G7-E8,1) -> 24186.6
A9: 5 | B9: 46020 | D9: =+ROUND(G8*0.01,1) -> 241.9 | E9: =ROUNDDOWN($C$4/84,1) -> 302.3 | F9: =+ROUND(D9+E9,1) -> 544.2 | G9: =+ROUND(G8-E9,1) -> 23884.3
A10: 6 | B10: 46051 | D10: =+ROUND(G9*0.01,1) -> 238.8 | E10: =ROUNDDOWN($C$4/84,1) -> 302.3 | F10: =+ROUND(D10+E10,1) -> 541.1 | G10: =+ROUND(G9-E10,1) -> 23582
A11: 7 | B11: 46081 | D11: =+ROUND(G10*0.01,1) -> 235.8 | E11: =ROUNDDOWN($C$4/84,1) -> 302.3 | F11: =+ROUND(D11+E11,1) -> 538.1 | G11: =+ROUND(G10-E11,1) -> 23279.7
A12: 8 | B12: 46110 | D12: =+ROUND(G11*0.01,1) -> 232.8 | E12: =ROUNDDOWN($C$4/84,1) -> 302.3 | F12: =+ROUND(D12+E12,1) -> 535.1 | G12: =+ROUND(G11-E12,1) -> 22977.4
A13: 9 | B13: 46141 | D13: =+ROUND(G12*0.01,1) -> 229.8 | E13: =ROUNDDOWN($C$4/84,1) -> 302.3 | F13: =+ROUND(D13+E13,1) -> 532.1 | G13: =+ROUND(G12-E13,1) -> 22675.1
A14: 10 | B14: 46171 | D14: =+ROUND(G13*0.01,1) -> 226.8 | E14: =ROUNDDOWN($C$4/84,1) -> 302.3 | F14: =+ROUND(D14+E14,1) -> 529.1 | G14: =+ROUND(G13-E14,1) -> 22372.8
A15: 11 | B15: 46202 | D15: =+ROUND(G14*0.01,1) -> 223.7 | E15: =ROUNDDOWN($C$4/84,1) -> 302.3 | F15: =+ROUND(D15+E15,1) -> 526 | G15: =+ROUND(G14-E15,1) -> 22070.5
A16: 12 | B16: 46232 | D16: =+ROUND(G15*0.01,1) -> 220.7 | E16: =ROUNDDOWN($C$4/84,1) -> 302.3 | F16: =+ROUND(D16+E16,1) -> 523 | G16: =+ROUND(G15-E16,1) -> 21768.2
A17: 13 | B17: 46263 | D17: =+ROUND(G16*0.01,1) -> 217.7 | E17: =ROUNDDOWN($C$4/84,1) -> 302.3 | F17: =+ROUND(D17+E17,1) -> 520 | G17: =+ROUND(G16-E17,1) -> 21465.9
A18: 14 | B18: 46294 | D18: =+ROUND(G17*0.01,1) -> 214.7 | E18: =ROUNDDOWN($C$4/84,1) -> 302.3 | F18: =+ROUND(D18+E18,1) -> 517 | G18: =+ROUND(G17-E18,1) -> 21163.6
A19: 15 | B19: 46324 | D19: =+ROUND(G18*0.01,1) -> 211.6 | E19: =ROUNDDOWN($C$4/84,1) -> 302.3 | F19: =+ROUND(D19+E19,1) -> 513.9 | G19: =+ROUND(G18-E19,1) -> 20861.3
... A87: 83 | B87: 48394 | D87: =+ROUND(G86*0.01,1) -> 6.1 | E87: =ROUNDDOWN($C$4/84,1) -> 302.3 | F87: =+ROUND(D87+E87,1) -> 308.4 | G87: =+ROUND(G86-E87,1) -> 304.9
A88: 84 | B88: 48424 | D88: =+ROUND(G87*0.01,1) -> 3 | E88: =ROUNDDOWN($C$4/84,1)+2.6 -> 304.9 | F88: =+ROUND(D88+E88,1) -> 307.9 | G88: =+ROUND(G87-E88,1) -> 0
A89: TOTAL | D89: =+SUM(D5:D88) -> 10794.3 | E89: =+SUM(E5:E88) -> 25395.8 | F89: =+SUM(F5:F88) -> 36190.1

Sheet 8
A1: SOCIO: LUIS FERNANDO CHAVEZ ALVAREZ
A2: AGOSTO 2025 - PRÉSTAMO
A3: PLAZO | B3: FECHA | C3: PRÉSTAMO S/. | D3: INTERES | E3: ABONO DE CAPITAL | F3: CUOTA | G3: SALDO
A4: 0 | B4: 45898 | C4: =+J7 -> 15426.2 | D4: 0.01 | G4: =+C4 -> 15426.2
A5: 1 | B5: 45929 | D5: =+ROUND(G4*0.01,1) -> 154.3 | E5: =ROUNDDOWN($C$4/60,1) -> 257.1 | F5: =+ROUND(D5+E5,1) -> 411.4 | G5: =+ROUND(G4-E5,1) -> 15169.1 | I5: SALDO | J5: 12584.8
A6: 2 | B6: 45959 | D6: =+ROUND(G5*0.01,1) -> 151.7 | E6: =ROUNDDOWN($C$4/60,1) -> 257.1 | F6: =+ROUND(D6+E6,1) -> 408.8 | G6: =+ROUND(G5-E6,1) -> 14912 | I6: PRESTAMO | J6: 2841.4
A7: 3 | B7: 45990 | D7: =+ROUND(G6*0.01,1) -> 149.1 | E7: =ROUNDDOWN($C$4/60,1) -> 257.1 | F7: =+ROUND(D7+E7,1) -> 406.2 | G7: =+ROUND(G6-E7,1) -> 14654.9 | I7: TOTAL | J7: =+SUM(J5:J6) -> 15426.2
A8: 4 | B8: 46020 | D8: =+ROUND(G7*0.01,1) -> 146.5 | E8: =ROUNDDOWN($C$4/60,1) -> 257.1 | F8: =+ROUND(D8+E8,1) -> 403.6 | G8: =+ROUND(G7-E8,1) -> 14397.8
A9: 5 | B9: 46051 | D9: =+ROUND(G8*0.01,1) -> 144 | E9: =ROUNDDOWN($C$4/60,1) -> 257.1 | F9: =+ROUND(D9+E9,1) -> 401.1 | G9: =+ROUND(G8-E9,1) -> 14140.7 | I9: INTERES | J9: =SUM(D5:D10) -> 887
A10: 6 | B10: 46081 | D10: =+ROUND(G9*0.01,1) -> 141.4 | E10: =ROUNDDOWN($C$4/60,1) -> 257.1 | F10: =+ROUND(D10+E10,1) -> 398.5 | G10: =+ROUND(G9-E10,1) -> 13883.6 | I10: SALDO | J10: =G10 -> 13883.6
A11: 7 | B11: 46110 | D11: =+ROUND(G10*0.01,1) -> 138.8 | E11: =ROUNDDOWN($C$4/60,1) -> 257.1 | F11: =+ROUND(D11+E11,1) -> 395.9 | G11: =+ROUND(G10-E11,1) -> 13626.5
A12: 8 | B12: 46141 | D12: =+ROUND(G11*0.01,1) -> 136.3 | E12: =ROUNDDOWN($C$4/60,1) -> 257.1 | F12: =+ROUND(D12+E12,1) -> 393.4 | G12: =+ROUND(G11-E12,1) -> 13369.4
A13: 9 | B13: 46171 | D13: =+ROUND(G12*0.01,1) -> 133.7 | E13: =ROUNDDOWN($C$4/60,1) -> 257.1 | F13: =+ROUND(D13+E13,1) -> 390.8 | G13: =+ROUND(G12-E13,1) -> 13112.3
A14: 10 | B14: 46202 | D14: =+ROUND(G13*0.01,1) -> 131.1 | E14: =ROUNDDOWN($C$4/60,1) -> 257.1 | F14: =+ROUND(D14+E14,1) -> 388.2 | G14: =+ROUND(G13-E14,1) -> 12855.2
A15: 11 | B15: 46232 | D15: =+ROUND(G14*0.01,1) -> 128.6 | E15: =ROUNDDOWN($C$4/60,1) -> 257.1 | F15: =+ROUND(D15+E15,1) -> 385.7 | G15: =+ROUND(G14-E15,1) -> 12598.1
A16: 12 | B16: 46263 | D16: =+ROUND(G15*0.01,1) -> 126 | E16: =ROUNDDOWN($C$4/60,1) -> 257.1 | F16: =+ROUND(D16+E16,1) -> 383.1 | G16: =+ROUND(G15-E16,1) -> 12341
A17: 13 | B17: 46294 | D17: =+ROUND(G16*0.01,1) -> 123.4 | E17: =ROUNDDOWN($C$4/60,1) -> 257.1 | F17: =+ROUND(D17+E17,1) -> 380.5 | G17: =+ROUND(G16-E17,1) -> 12083.9
A18: 14 | B18: 46324 | D18: =+ROUND(G17*0.01,1) -> 120.8 | E18: =ROUNDDOWN($C$4/60,1) -> 257.1 | F18: =+ROUND(D18+E18,1) -> 377.9 | G18: =+ROUND(G17-E18,1) -> 11826.8
A19: 15 | B19: 46355 | D19: =+ROUND(G18*0.01,1) -> 118.3 | E19: =ROUNDDOWN($C$4/60,1) -> 257.1 | F19: =+ROUND(D19+E19,1) -> 375.4 | G19: =+ROUND(G18-E19,1) -> 11569.7
A20: 16 | B20: 46385 | D20: =+ROUND(G19*0.01,1) -> 115.7 | E20: =ROUNDDOWN($C$4/60,1) -> 257.1 | F20: =+ROUND(D20+E20,1) -> 372.8 | G20: =+ROUND(G19-E20,1) -> 11312.6
A21: 17 | B21: 46416 | D21: =+ROUND(G20*0.01,1) -> 113.1 | E21: =ROUNDDOWN($C$4/60,1) -> 257.1 | F21: =+ROUND(D21+E21,1) -> 370.2 | G21: =+ROUND(G20-E21,1) -> 11055.5
A22: 18 | B22: 46446 | D22: =+ROUND(G21*0.01,1) -> 110.6 | E22: =ROUNDDOWN($C$4/60,1) -> 257.1 | F22: =+ROUND(D22+E22,1) -> 367.7 | G22: =+ROUND(G21-E22,1) -> 10798.4
... A63: 59 | B63: 47693 | D63: =+ROUND(G62*0.01,1) -> 5.1 | E63: =ROUNDDOWN($C$4/60,1) -> 257.1 | F63: =+ROUND(D63+E63,1) -> 262.2 | G63: =+ROUND(G62-E63,1) -> 257.3
A64: 60 | B64: 47724 | D64: =+ROUND(G63*0.01,1) -> 2.6 | E64: =ROUNDDOWN($C$4/60,1)+0.2 -> 257.3 | F64: =+ROUND(D64+E64,1) -> 259.9 | G64: =+ROUND(G63-E64,1) -> 0
A65: TOTAL | D65: =+SUM(D5:D64) -> 4705.1 | E65: =+SUM(E5:E64) -> 15426.2 | F65: =+SUM(F5:F64) -> 20131.3
A67: FEBRERO 2026 - PRÉSTAMO
A68: PLAZO | B68: FECHA | C68: PRÉSTAMO S/. | D68: INTERES | E68: ABONO DE CAPITAL | F68: CUOTA | G68: SALDO
A69: 0 | B69: 45898 | C69: =+J72 -> 28883.6 | D69: 0.01 | G69: =+C69 -> 28883.6
A70: 1 | B70: 45929 | D70: =+ROUND(G69*0.01,1) -> 288.8 | E70: =ROUND($C$69/60,1) -> 481.4 | F70: =+ROUND(D70+E70,1) -> 770.2 | G70: =+ROUND(G69-E70,1) -> 28402.2 | I70: SALDO | J70: =J10 -> 13883.6
A71: 2 | B71: 45959 | D71: =+ROUND(G70*0.01,1) -> 284 | E71: =ROUND($C$69/60,1) -> 481.4 | F71: =+ROUND(D71+E71,1) -> 765.4 | G71: =+ROUND(G70-E71,1) -> 27920.8 | I71: PRESTAMO | J71: 15000
A72: 3 | B72: 45990 | D72: =+ROUND(G71*0.01,1) -> 279.2 | E72: =ROUND($C$69/60,1) -> 481.4 | F72: =+ROUND(D72+E72,1) -> 760.6 | G72: =+ROUND(G71-E72,1) -> 27439.4 | I72: TOTAL | J72: =+SUM(J70:J71) -> 28883.6
A73: 4 | B73: 46020 | D73: =+ROUND(G72*0.01,1) -> 274.4 | E73: =ROUND($C$69/60,1) -> 481.4 | F73: =+ROUND(D73+E73,1) -> 755.8 | G73: =+ROUND(G72-E73,1) -> 26958
A74: 5 | B74: 46051 | D74: =+ROUND(G73*0.01,1) -> 269.6 | E74: =ROUND($C$69/60,1) -> 481.4 | F74: =+ROUND(D74+E74,1) -> 751 | G74: =+ROUND(G73-E74,1) -> 26476.6
A75: 6 | B75: 46081 | D75: =+ROUND(G74*0.01,1) -> 264.8 | E75: =ROUND($C$69/60,1) -> 481.4 | F75: =+ROUND(D75+E75,1) -> 746.2 | G75: =+ROUND(G74-E75,1) -> 25995.2
A76: 7 | B76: 46110 | D76: =+ROUND(G75*0.01,1) -> 260 | E76: =ROUND($C$69/60,1) -> 481.4 | F76: =+ROUND(D76+E76,1) -> 741.4 | G76: =+ROUND(G75-E76,1) -> 25513.8
A77: 8 | B77: 46141 | D77: =+ROUND(G76*0.01,1) -> 255.1 | E77: =ROUND($C$69/60,1) -> 481.4 | F77: =+ROUND(D77+E77,1) -> 736.5 | G77: =+ROUND(G76-E77,1) -> 25032.4
A78: 9 | B78: 46171 | D78: =+ROUND(G77*0.01,1) -> 250.3 | E78: =ROUND($C$69/60,1) -> 481.4 | F78: =+ROUND(D78+E78,1) -> 731.7 | G78: =+ROUND(G77-E78,1) -> 24551
A79: 10 | B79: 46202 | D79: =+ROUND(G78*0.01,1) -> 245.5 | E79: =ROUND($C$69/60,1) -> 481.4 | F79: =+ROUND(D79+E79,1) -> 726.9 | G79: =+ROUND(G78-E79,1) -> 24069.6
A80: 11 | B80: 46232 | D80: =+ROUND(G79*0.01,1) -> 240.7 | E80: =ROUND($C$69/60,1) -> 481.4 | F80: =+ROUND(D80+E80,1) -> 722.1 | G80: =+ROUND(G79-E80,1) -> 23588.2
A81: 12 | B81: 46263 | D81: =+ROUND(G80*0.01,1) -> 235.9 | E81: =ROUND($C$69/60,1) -> 481.4 | F81: =+ROUND(D81+E81,1) -> 717.3 | G81: =+ROUND(G80-E81,1) -> 23106.8
...

Sheet 9
A1: SOCIO: JORGE EMILIANO CHAVEZ CHAVEZ
A2: JUNIO 2025 - PRÉSTAMO
A3: PLAZO | B3: FECHA | C3: PRÉSTAMO S/. | D3: INTERES | E3: ABONO DE CAPITAL | F3: CUOTA | G3: SALDO
A4: 0 | B4: 45837 | C4: =+J7 -> 46124.4 | D4: 0.01 | G4: =+C4 -> 46124.4
A5: 1 | B5: 45867 | D5: =+ROUND(G4*0.01,1) -> 461.2 | E5: =ROUNDDOWN(C4/84,1) -> 549.1 | F5: =+ROUND(D5+E5,1) -> 1010.3 | G5: =+ROUND(G4-E5,1) -> 45575.3 | I5: SALDO | J5: 51124.4
A6: 2 | B6: 45898 | D6: =+ROUND(G5*0.01,1) -> 455.8 | E6: =ROUNDDOWN($C$4/84,1) -> 549.1 | F6: =+ROUND(D6+E6,1) -> 1004.9 | G6: =+ROUND(G5-E6,1) -> 45026.2 | I6: DEVOLUCIÓN | J6: -5000
A7: 3 | B7: 45929 | D7: =+ROUND(G6*0.01,1) -> 450.3 | E7: =ROUNDDOWN($C$4/84,1) -> 549.1 | F7: =+ROUND(D7+E7,1) -> 999.4 | G7: =+ROUND(G6-E7,1) -> 44477.1 | I7: TOTAL | J7: =+SUM(J5:J6) -> 46124.4
A8: 4 | B8: 45959 | D8: =+ROUND(G7*0.01,1) -> 444.8 | E8: =ROUNDDOWN($C$4/84,1) -> 549.1 | F8: =+ROUND(D8+E8,1) -> 993.9 | G8: =+ROUND(G7-E8,1) -> 43928
A9: 5 | B9: 45990 | D9: =+ROUND(G8*0.01,1) -> 439.3 | E9: =ROUNDDOWN($C$4/84,1) -> 549.1 | F9: =+ROUND(D9+E9,1) -> 988.4 | G9: =+ROUND(G8-E9,1) -> 43378.9
A10: 6 | B10: 46020 | D10: =+ROUND(G9*0.01,1) -> 433.8 | E10: =ROUNDDOWN($C$4/84,1) -> 549.1 | F10: =+ROUND(D10+E10,1) -> 982.9 | G10: =+ROUND(G9-E10,1) -> 42829.8
A11: 7 | B11: 46051 | D11: =+ROUND(G10*0.01,1) -> 428.3 | E11: =ROUNDDOWN($C$4/84,1) -> 549.1 | F11: =+ROUND(D11+E11,1) -> 977.4 | G11: =+ROUND(G10-E11,1) -> 42280.7
A12: 8 | B12: 46081 | D12: =+ROUND(G11*0.01,1) -> 422.8 | E12: =ROUNDDOWN($C$4/84,1) -> 549.1 | F12: =+ROUND(D12+E12,1) -> 971.9 | G12: =+ROUND(G11-E12,1) -> 41731.6
A13: 9 | B13: 46110 | D13: =+ROUND(G12*0.01,1) -> 417.3 | E13: =ROUNDDOWN($C$4/84,1) -> 549.1 | F13: =+ROUND(D13+E13,1) -> 966.4 | G13: =+ROUND(G12-E13,1) -> 41182.5
A14: 10 | B14: 46141 | D14: =+ROUND(G13*0.01,1) -> 411.8 | E14: =ROUNDDOWN($C$4/84,1) -> 549.1 | F14: =+ROUND(D14+E14,1) -> 960.9 | G14: =+ROUND(G13-E14,1) -> 40633.4
A15: 11 | B15: 46171 | D15: =+ROUND(G14*0.01,1) -> 406.3 | E15: =ROUNDDOWN($C$4/84,1) -> 549.1 | F15: =+ROUND(D15+E15,1) -> 955.4 | G15: =+ROUND(G14-E15,1) -> 40084.3
A16: 12 | B16: 46202 | D16: =+ROUND(G15*0.01,1) -> 400.8 | E16: =ROUNDDOWN($C$4/84,1) -> 549.1 | F16: =+ROUND(D16+E16,1) -> 949.9 | G16: =+ROUND(G15-E16,1) -> 39535.2
A17: 13 | B17: 46232 | D17: =+ROUND(G16*0.01,1) -> 395.4 | E17: =ROUNDDOWN($C$4/84,1) -> 549.1 | F17: =+ROUND(D17+E17,1) -> 944.5 | G17: =+ROUND(G16-E17,1) -> 38986.1
A18: 14 | B18: 46263 | D18: =+ROUND(G17*0.01,1) -> 389.9 | E18: =ROUNDDOWN($C$4/84,1) -> 549.1 | F18: =+ROUND(D18+E18,1) -> 939 | G18: =+ROUND(G17-E18,1) -> 38437
A19: 15 | B19: 46294 | D19: =+ROUND(G18*0.01,1) -> 384.4 | E19: =ROUNDDOWN($C$4/84,1) -> 549.1 | F19: =+ROUND(D19+E19,1) -> 933.5 | G19: =+ROUND(G18-E19,1) -> 37887.9
... A88: 84 | B88: 48394 | D88: =+ROUND(G87*0.01,1) -> 5.5 | E88: =ROUNDDOWN($C$4/84,1) -> 549.1 | F88: =+ROUND(D88+E88,1) -> 554.6 | G88: =+ROUND(G87-E88,1) -> 0
A89: TOTAL | D89: =+SUM(D5:D88) -> 19603 | E89: =+SUM(E5:E88) -> 46124.4 | F89: =+SUM(F5:F88) -> 65727.4

Sheet 10
A1: SOCIO: CHAVEZ CHAVEZ PEDRO
A2: AGOSTO 2024 - PRÉSTAMO
A3: PLAZO | B3: FECHA | C3: PRÉSTAMO S/. | D3: INTERES | E3: ABONO DE CAPITAL | F3: CUOTA | G3: SALDO
A4: 0 | B4: 45533 | C4: =+J7 -> 14825.9 | D4: 0.01 | G4: =+C4 -> 14825.9
A5: 1 | B5: 45564 | D5: =+ROUND(G4*0.01,1) -> 148.3 | E5: =ROUNDUP($C$4/48,1) -> 308.9 | F5: =+ROUND(D5+E5,1) -> 457.2 | G5: =+ROUND(G4-E5,1) -> 14517 | I5: SALDO | J5: 3039.9
A6: 2 | B6: 45594 | D6: =+ROUND(G5*0.01,1) -> 145.2 | E6: =ROUNDUP($C$4/48,1) -> 308.9 | F6: =+ROUND(D6+E6,1) -> 454.1 | G6: =+ROUND(G5-E6,1) -> 14208.1 | I6: PRESTAMO | J6: 11786
A7: 3 | B7: 45625 | D7: =+ROUND(G6*0.01,1) -> 142.1 | E7: =ROUNDUP($C$4/48,1) -> 308.9 | F7: =+ROUND(D7+E7,1) -> 451 | G7: =+ROUND(G6-E7,1) -> 13899.2 | I7: TOTAL | J7: =+SUM(J5:J6) -> 14825.9
A8: 4 | B8: 45655 | D8: =+ROUND(G7*0.01,1) -> 139 | E8: =ROUNDUP($C$4/48,1) -> 308.9 | F8: =+ROUND(D8+E8,1) -> 447.9 | G8: =+ROUND(G7-E8,1) -> 13590.3
A9: 5 | B9: 45686 | D9: =+ROUND(G8*0.01,1) -> 135.9 | E9: =ROUNDUP($C$4/48,1) -> 308.9 | F9: =+ROUND(D9+E9,1) -> 444.8 | G9: =+ROUND(G8-E9,1) -> 13281.4
A10: 6 | B10: 45716 | D10: =+ROUND(G9*0.01,1) -> 132.8 | E10: =ROUNDUP($C$4/48,1) -> 308.9 | F10: =+ROUND(D10+E10,1) -> 441.7 | G10: =+ROUND(G9-E10,1) -> 12972.5
A11: 7 | B11: 45745 | D11: =+ROUND(G10*0.01,1) -> 129.7 | E11: =ROUNDUP($C$4/48,1) -> 308.9 | F11: =+ROUND(D11+E11,1) -> 438.6 | G11: =+ROUND(G10-E11,1) -> 12663.6
A12: 8 | B12: 45776 | D12: =+ROUND(G11*0.01,1) -> 126.6 | E12: =ROUNDUP($C$4/48,1) -> 308.9 | F12: =+ROUND(D12+E12,1) -> 435.5 | G12: =+ROUND(G11-E12,1) -> 12354.7
A13: 9 | B13: 45806 | D13: =+ROUND(G12*0.01,1) -> 123.5 | E13: =ROUNDUP($C$4/48,1) -> 308.9 | F13: =+ROUND(D13+E13,1) -> 432.4 | G13: =+ROUND(G12-E13,1) -> 12045.8
A14: 10 | B14: 45837 | D14: =+ROUND(G13*0.01,1) -> 120.5 | E14: =ROUNDUP($C$4/48,1) -> 308.9 | F14: =+ROUND(D14+E14,1) -> 429.4 | G14: =+ROUND(G13-E14,1) -> 11736.9
A15: 11 | B15: 45867 | D15: =+ROUND(G14*0.01,1) -> 117.4 | E15: =ROUNDUP($C$4/48,1) -> 308.9 | F15: =+ROUND(D15+E15,1) -> 426.3 | G15: =+ROUND(G14-E15,1) -> 11428
A16: 12 | B16: 45898 | D16: =+ROUND(G15*0.01,1) -> 114.3 | E16: =ROUNDUP($C$4/48,1) -> 308.9 | F16: =+ROUND(D16+E16,1) -> 423.2 | G16: =+ROUND(G15-E16,1) -> 11119.1
A17: 13 | B17: 45929 | D17: =+ROUND(G16*0.01,1) -> 111.2 | E17: =ROUNDUP($C$4/48,1) -> 308.9 | F17: =+ROUND(D17+E17,1) -> 420.1 | G17: =+ROUND(G16-E17,1) -> 10810.2 | I17: INTERES | J17: =SUM(D5:D18) -> 1794.6
A18: 14 | B18: 45959 | D18: =+ROUND(G17*0.01,1) -> 108.1 | E18: =ROUNDUP($C$4/48,1) -> 308.9 | F18: =+ROUND(D18+E18,1) -> 417 | G18: =+ROUND(G17-E18,1) -> 10501.3 | I18: SALDO | J18: =G18 -> 10501.3
A19: 15 | B19: 45990 | D19: =+ROUND(G18*0.01,1) -> 105 | E19: =ROUNDUP($C$4/48,1) -> 308.9 | F19: =+ROUND(D19+E19,1) -> 413.9 | G19: =+ROUND(G18-E19,1) -> 10192.4
A20: 16 | B20: 46020 | D20: =+ROUND(G19*0.01,1) -> 101.9 | E20: =ROUNDUP($C$4/48,1) -> 308.9 | F20: =+ROUND(D20+E20,1) -> 410.8 | G20: =+ROUND(G19-E20,1) -> 9883.5
A21: 17 | B21: 46051 | D21: =+ROUND(G20*0.01,1) -> 98.8 | E21: =ROUNDUP($C$4/48,1) -> 308.9 | F21: =+ROUND(D21+E21,1) -> 407.7 | G21: =+ROUND(G20-E21,1) -> 9574.6
A22: 18 | B22: 46081 | D22: =+ROUND(G21*0.01,1) -> 95.7 | E22: =ROUNDUP($C$4/48,1) -> 308.9 | F22: =+ROUND(D22+E22,1) -> 404.6 | G22: =+ROUND(G21-E22,1) -> 9265.7
A23: 19 | B23: 46110 | D23: =+ROUND(G22*0.01,1) -> 92.7 | E23: =ROUNDUP($C$4/48,1) -> 308.9 | F23: =+ROUND(D23+E23,1) -> 401.6 | G23: =+ROUND(G22-E23,1) -> 8956.8
A24: 20 | B24: 46141 | D24: =+ROUND(G23*0.01,1) -> 89.6 | E24: =ROUNDUP($C$4/48,1) -> 308.9 | F24: =+ROUND(D24+E24,1) -> 398.5 | G24: =+ROUND(G23-E24,1) -> 8647.9
A25: 21 | B25: 46171 | D25: =+ROUND(G24*0.01,1) -> 86.5 | E25: =ROUNDUP($C$4/48,1) -> 308.9 | F25: =+ROUND(D25+E25,1) -> 395.4 | G25: =+ROUND(G24-E25,1) -> 8339
A26: 22 | B26: 46202 | D26: =+ROUND(G25*0.01,1) -> 83.4 | E26: =ROUNDUP($C$4/48,1) -> 308.9 | F26: =+ROUND(D26+E26,1) -> 392.3 | G26: =+ROUND(G25-E26,1) -> 8030.1
A27: 23 | B27: 46232 | D27: =+ROUND(G26*0.01,1) -> 80.3 | E27: =ROUNDUP($C$4/48,1) -> 308.9 | F27: =+ROUND(D27+E27,1) -> 389.2 | G27: =+ROUND(G26-E27,1) -> 7721.2
A28: 24 | B28: 46263 | D28: =+ROUND(G27*0.01,1) -> 77.2 | E28: =ROUNDUP($C$4/48,1) -> 308.9 | F28: =+ROUND(D28+E28,1) -> 386.1 | G28: =+ROUND(G27-E28,1) -> 7412.3
A29: 25 | B29: 46294 | D29: =+ROUND(G28*0.01,1) -> 74.1 | E29: =ROUNDUP($C$4/48,1) -> 308.9 | F29: =+ROUND(D29+E29,1) -> 383 | G29: =+ROUND(G28-E29,1) -> 7103.4
A30: 26 | B30: 46324 | D30: =+ROUND(G29*0.01,1) -> 71 | E30: =ROUNDUP($C$4/48,1) -> 308.9 | F30: =+ROUND(D30+E30,1) -> 379.9 | G30: =+ROUND(G29-E30,1) -> 6794.5
... A51: 47 | B51: 46963 | D51: =+ROUND(G50*0.01,1) -> 6.2 | E51: =ROUNDUP($C$4/48,1) -> 308.9 | F51: =+ROUND(D51+E51,1) -> 315.1 | G51: =+ROUND(G50-E51,1) -> 307.6
A52: 48 | B52: 46994 | D52: =+ROUND(G51*0.01,1) -> 3.1 | E52: =ROUNDUP($C$4/48,1)-1.3 -> 307.6 | F52: =+ROUND(D52+E52,1) -> 310.7 | G52: =+ROUND(G51-E52,1) -> 0
A53: TOTAL | D53: =+SUM(D5:D52) -> 3632.1 | E53: =+SUM(E5:E52) -> 14825.9 | F53: =+SUM(F5:F52) -> 18458
A55: SOCIO: CHAVEZ CHAVEZ PEDRO
A56: OCTUBRE 2025 - PRÉSTAMO
A57: PLAZO | B57: FECHA | C57: PRÉSTAMO S/. | D57: INTERES | E57: ABONO DE CAPITAL | F57: CUOTA | G57: SALDO
A58: 0 | B58: 45959 | C58: =+J61 -> 20501.3 | D58: 0.01 | G58: =+C58 -> 20501.3
A59: 1 | B59: 45990 | D59: =+ROUND(G58*0.01,1) -> 205 | E59: =ROUNDUP($C$58/36,1) -> 569.5 | F59: =+ROUND(D59+E59,1) -> 774.5 | G59: =+ROUND(G58-E59,1) -> 19931.8 | I59: SALDO | J59: =G18 -> 10501.3
A60: 2 | B60: 46020 | D60: =+ROUND(G59*0.01,1) -> 199.3 | E60: =ROUNDUP($C$58/36,1) -> 569.5 | F60: =+ROUND(D60+E60,1) -> 768.8 | G60: =+ROUND(G59-E60,1) -> 19362.3 | I60: PRESTAMO | J60: 10000
A61: 3 | B61: 46051 | D61: =+ROUND(G60*0.01,1) -> 193.6 | E61: =ROUNDUP($C$58/36,1) -> 569.5 | F61: =+ROUND(D61+E61,1) -> 763.1 | G61: =+ROUND(G60-E61,1) -> 18792.8 | I61: TOTAL | J61: =+SUM(J59:J60) -> 20501.3
...

Sheet 11
A1: SOCIO: EDWIN FELIX CHAVEZ MARIN
A2: SETIEMBRE 2025 - PRÉSTAMO
A3: PLAZO | B3: FECHA | C3: PRÉSTAMO S/. | D3: INTERES | E3: ABONO DE CAPITAL | F3: CUOTA | G3: SALDO
A4: 0 | B4: 45929 | C4: =+J7 -> 52744.1 | D4: 0.01 | G4: =+C4 -> 52744.1
A5: 1 | B5: 45959 | D5: =+ROUND(G4*0.01,1) -> 527.4 | E5: =ROUNDDOWN(C4/84,1) -> 627.9 | F5: =+ROUND(D5+E5,1) -> 1155.3 | G5: =+ROUND(G4-E5,1) -> 52116.2 | I5: SALDO | J5: 42953
A6: 2 | B6: 45990 | D6: =+ROUND(G5*0.01,1) -> 521.2 | E6: =ROUNDDOWN($C$4/84,1) -> 627.9 | F6: =+ROUND(D6+E6,1) -> 1149.1 | G6: =+ROUND(G5-E6,1) -> 51488.3 | I6: PRESTAMO | J6: 9791.1
A7: 3 | B7: 46020 | D7: =+ROUND(G6*0.01,1) -> 514.9 | E7: =ROUNDDOWN($C$4/84,1) -> 627.9 | F7: =+ROUND(D7+E7,1) -> 1142.8 | G7: =+ROUND(G6-E7,1) -> 50860.4 | I7: TOTAL | J7: =+SUM(J5:J6) -> 52744.1
A8: 4 | B8: 46051 | D8: =+ROUND(G7*0.01,1) -> 508.6 | E8: =ROUNDDOWN($C$4/84,1) -> 627.9 | F8: =+ROUND(D8+E8,1) -> 1136.5 | G8: =+ROUND(G7-E8,1) -> 50232.5
A9: 5 | B9: 46081 | D9: =+ROUND(G8*0.01,1) -> 502.3 | E9: =ROUNDDOWN($C$4/84,1) -> 627.9 | F9: =+ROUND(D9+E9,1) -> 1130.2 | G9: =+ROUND(G8-E9,1) -> 49604.6
A10: 6 | B10: 46110 | D10: =+ROUND(G9*0.01,1) -> 496 | E10: =ROUNDDOWN($C$4/84,1) -> 627.9 | F10: =+ROUND(D10+E10,1) -> 1123.9 | G10: =+ROUND(G9-E10,1) -> 48976.7
A11: 7 | B11: 46141 | D11: =+ROUND(G10*0.01,1) -> 489.8 | E11: =ROUNDDOWN($C$4/84,1) -> 627.9 | F11: =+ROUND(D11+E11,1) -> 1117.7 | G11: =+ROUND(G10-E11,1) -> 48348.8
A12: 8 | B12: 46171 | D12: =+ROUND(G11*0.01,1) -> 483.5 | E12: =ROUNDDOWN($C$4/84,1) -> 627.9 | F12: =+ROUND(D12+E12,1) -> 1111.4 | G12: =+ROUND(G11-E12,1) -> 47720.9
A13: 9 | B13: 46202 | D13: =+ROUND(G12*0.01,1) -> 477.2 | E13: =ROUNDDOWN($C$4/84,1) -> 627.9 | F13: =+ROUND(D13+E13,1) -> 1105.1 | G13: =+ROUND(G12-E13,1) -> 47093
A14: 10 | B14: 46232 | D14: =+ROUND(G13*0.01,1) -> 470.9 | E14: =ROUNDDOWN($C$4/84,1) -> 627.9 | F14: =+ROUND(D14+E14,1) -> 1098.8 | G14: =+ROUND(G13-E14,1) -> 46465.1
A15: 11 | B15: 46263 | D15: =+ROUND(G14*0.01,1) -> 464.7 | E15: =ROUNDDOWN($C$4/84,1) -> 627.9 | F15: =+ROUND(D15+E15,1) -> 1092.6 | G15: =+ROUND(G14-E15,1) -> 45837.2
A16: 12 | B16: 46294 | D16: =+ROUND(G15*0.01,1) -> 458.4 | E16: =ROUNDDOWN($C$4/84,1) -> 627.9 | F16: =+ROUND(D16+E16,1) -> 1086.3 | G16: =+ROUND(G15-E16,1) -> 45209.3
A17: 13 | B17: 46324 | D17: =+ROUND(G16*0.01,1) -> 452.1 | E17: =ROUNDDOWN($C$4/84,1) -> 627.9 | F17: =+ROUND(D17+E17,1) -> 1080 | G17: =+ROUND(G16-E17,1) -> 44581.4
A18: 14 | B18: 46355 | D18: =+ROUND(G17*0.01,1) -> 445.8 | E18: =ROUNDDOWN($C$4/84,1) -> 627.9 | F18: =+ROUND(D18+E18,1) -> 1073.7 | G18: =+ROUND(G17-E18,1) -> 43953.5
A19: 15 | B19: 46385 | D19: =+ROUND(G18*0.01,1) -> 439.5 | E19: =ROUNDDOWN($C$4/84,1) -> 627.9 | F19: =+ROUND(D19+E19,1) -> 1067.4 | G19: =+ROUND(G18-E19,1) -> 43325.6
... A87: 83 | B87: 48455 | D87: =+ROUND(G86*0.01,1) -> 12.6 | E87: =ROUNDDOWN($C$4/84,1) -> 627.9 | F87: =+ROUND(D87+E87,1) -> 640.5 | G87: =+ROUND(G86-E87,1) -> 628.4
A88: 84 | B88: 48486 | D88: =+ROUND(G87*0.01,1) -> 6.3 | E88: =ROUNDDOWN($C$4/84,1)+0.5 -> 628.4 | F88: =+ROUND(D88+E88,1) -> 634.7 | G88: =+ROUND(G87-E88,1) -> 0
A89: TOTAL | D89: =+SUM(D5:D88) -> 22416.5 | E89: =+SUM(E5:E88) -> 52744.1 | F89: =+SUM(F5:F88) -> 75160.6

Sheet 12
A1: SOCIO: MELBA GLADIS CHAVEZ QUEVEDO
A2: OCTUBRE 2024 - PRÉSTAMO
A3: PLAZO | B3: FECHA | C3: PRÉSTAMO S/. | D3: INTERES | E3: ABONO DE CAPITAL | F3: CUOTA | G3: SALDO
A4: 0 | B4: 45594 | C4: =+J6 -> 14320.9 | D4: 0.01 | G4: =+C4 -> 14320.9
A5: 1 | B5: 45625 | D5: =+ROUND(G4*0.01,1) -> 143.2 | E5: =ROUNDUP($C$4/60,1) -> 238.7 | F5: =+ROUND(D5+E5,1) -> 381.9 | G5: =+ROUND(G4-E5,1) -> 14082.2 | I5: PRÉSTAMO | J5: 14320.9
A6: 2 | B6: 45655 | D6: =+ROUND(G5*0.01,1) -> 140.8 | E6: =ROUNDUP($C$4/60,1) -> 238.7 | F6: =+ROUND(D6+E6,1) -> 379.5 | G6: =+ROUND(G5-E6,1) -> 13843.5 | I6: TOTAL | J6: =+SUM(J5) -> 14320.9
A7: 3 | B7: 45686 | D7: =+ROUND(G6*0.01,1) -> 138.4 | E7: =ROUNDUP($C$4/60,1) -> 238.7 | F7: =+ROUND(D7+E7,1) -> 377.1 | G7: =+ROUND(G6-E7,1) -> 13604.8
A8: 4 | B8: 45716 | D8: =+ROUND(G7*0.01,1) -> 136 | E8: =ROUNDUP($C$4/60,1) -> 238.7 | F8: =+ROUND(D8+E8,1) -> 374.7 | G8: =+ROUND(G7-E8,1) -> 13366.1
A9: 5 | B9: 45745 | D9: =+ROUND(G8*0.01,1) -> 133.7 | E9: =ROUNDUP($C$4/60,1) -> 238.7 | F9: =+ROUND(D9+E9,1) -> 372.4 | G9: =+ROUND(G8-E9,1) -> 13127.4
A10: 6 | B10: 45776 | D10: =+ROUND(G9*0.01,1) -> 131.3 | E10: =ROUNDUP($C$4/60,1) -> 238.7 | F10: =+ROUND(D10+E10,1) -> 370 | G10: =+ROUND(G9-E10,1) -> 12888.7
A11: 7 | B11: 45806 | D11: =+ROUND(G10*0.01,1) -> 128.9 | E11: =ROUNDUP($C$4/60,1) -> 238.7 | F11: =+ROUND(D11+E11,1) -> 367.6 | G11: =+ROUND(G10-E11,1) -> 12650
A12: 8 | B12: 45837 | D12: =+ROUND(G11*0.01,1) -> 126.5 | E12: =ROUNDUP($C$4/60,1) -> 238.7 | F12: =+ROUND(D12+E12,1) -> 365.2 | G12: =+ROUND(G11-E12,1) -> 12411.3
A13: 9 | B13: 45867 | D13: =+ROUND(G12*0.01,1) -> 124.1 | E13: =ROUNDUP($C$4/60,1) -> 238.7 | F13: =+ROUND(D13+E13,1) -> 362.8 | G13: =+ROUND(G12-E13,1) -> 12172.6
A14: 10 | B14: 45898 | D14: =+ROUND(G13*0.01,1) -> 121.7 | E14: =ROUNDUP($C$4/60,1) -> 238.7 | F14: =+ROUND(D14+E14,1) -> 360.4 | G14: =+ROUND(G13-E14,1) -> 11933.9
A15: 11 | B15: 45929 | D15: =+ROUND(G14*0.01,1) -> 119.3 | E15: =ROUNDUP($C$4/60,1) -> 238.7 | F15: =+ROUND(D15+E15,1) -> 358 | G15: =+ROUND(G14-E15,1) -> 11695.2
A16: 12 | B16: 45959 | D16: =+ROUND(G15*0.01,1) -> 117 | E16: =ROUNDUP($C$4/60,1) -> 238.7 | F16: =+ROUND(D16+E16,1) -> 355.7 | G16: =+ROUND(G15-E16,1) -> 11456.5
A17: 13 | B17: 45990 | D17: =+ROUND(G16*0.01,1) -> 114.6 | E17: =ROUNDUP($C$4/60,1) -> 238.7 | F17: =+ROUND(D17+E17,1) -> 353.3 | G17: =+ROUND(G16-E17,1) -> 11217.8
A18: 14 | B18: 46020 | D18: =+ROUND(G17*0.01,1) -> 112.2 | E18: =ROUNDUP($C$4/60,1) -> 238.7 | F18: =+ROUND(D18+E18,1) -> 350.9 | G18: =+ROUND(G17-E18,1) -> 10979.1 | I18: INTERES | J18: =SUM(D5:D19) -> 1897.5
A19: 15 | B19: 46051 | D19: =+ROUND(G18*0.01,1) -> 109.8 | E19: =ROUNDUP($C$4/60,1) -> 238.7 | F19: =+ROUND(D19+E19,1) -> 348.5 | G19: =+ROUND(G18-E19,1) -> 10740.4 | I19: SALDO | J19: =G19 -> 10740.4
A20: 16 | B20: 46081 | D20: =+ROUND(G19*0.01,1) -> 107.4 | E20: =ROUNDUP($C$4/60,1) -> 238.7 | F20: =+ROUND(D20+E20,1) -> 346.1 | G20: =+ROUND(G19-E20,1) -> 10501.7
A21: 17 | B21: 46110 | D21: =+ROUND(G20*0.01,1) -> 105 | E21: =ROUNDUP($C$4/60,1) -> 238.7 | F21: =+ROUND(D21+E21,1) -> 343.7 | G21: =+ROUND(G20-E21,1) -> 10263
A22: 18 | B22: 46141 | D22: =+ROUND(G21*0.01,1) -> 102.6 | E22: =ROUNDUP($C$4/60,1) -> 238.7 | F22: =+ROUND(D22+E22,1) -> 341.3 | G22: =+ROUND(G21-E22,1) -> 10024.3
A23: 19 | B23: 46171 | D23: =+ROUND(G22*0.01,1) -> 100.2 | E23: =ROUNDUP($C$4/60,1) -> 238.7 | F23: =+ROUND(D23+E23,1) -> 338.9 | G23: =+ROUND(G22-E23,1) -> 9785.6
A24: 20 | B24: 46202 | D24: =+ROUND(G23*0.01,1) -> 97.9 | E24: =ROUNDUP($C$4/60,1) -> 238.7 | F24: =+ROUND(D24+E24,1) -> 336.6 | G24: =+ROUND(G23-E24,1) -> 9546.9
A25: 21 | B25: 46232 | D25: =+ROUND(G24*0.01,1) -> 95.5 | E25: =ROUNDUP($C$4/60,1) -> 238.7 | F25: =+ROUND(D25+E25,1) -> 334.2 | G25: =+ROUND(G24-E25,1) -> 9308.2
A26: 22 | B26: 46263 | D26: =+ROUND(G25*0.01,1) -> 93.1 | E26: =ROUNDUP($C$4/60,1) -> 238.7 | F26: =+ROUND(D26+E26,1) -> 331.8 | G26: =+ROUND(G25-E26,1) -> 9069.5
A27: 23 | B27: 46294 | D27: =+ROUND(G26*0.01,1) -> 90.7 | E27: =ROUNDUP($C$4/60,1) -> 238.7 | F27: =+ROUND(D27+E27,1) -> 329.4 | G27: =+ROUND(G26-E27,1) -> 8830.8
A28: 24 | B28: 46324 | D28: =+ROUND(G27*0.01,1) -> 88.3 | E28: =ROUNDUP($C$4/60,1) -> 238.7 | F28: =+ROUND(D28+E28,1) -> 327 | G28: =+ROUND(G27-E28,1) -> 8592.1
A29: 25 | B29: 46355 | D29: =+ROUND(G28*0.01,1) -> 85.9 | E29: =ROUNDUP($C$4/60,1) -> 238.7 | F29: =+ROUND(D29+E29,1) -> 324.6 | G29: =+ROUND(G28-E29,1) -> 8353.4
A30: 26 | B30: 46385 | D30: =+ROUND(G29*0.01,1) -> 83.5 | E30: =ROUNDUP($C$4/60,1) -> 238.7 | F30: =+ROUND(D30+E30,1) -> 322.2 | G30: =+ROUND(G29-E30,1) -> 8114.7
A31: 27 | B31: 46416 | D31: =+ROUND(G30*0.01,1) -> 81.1 | E31: =ROUNDUP($C$4/60,1) -> 238.7 | F31: =+ROUND(D31+E31,1) -> 319.8 | G31: =+ROUND(G30-E31,1) -> 7876
... A63: 59 | B63: 47390 | D63: =+ROUND(G62*0.01,1) -> 4.8 | E63: =ROUNDUP($C$4/60,1) -> 238.7 | F63: =+ROUND(D63+E63,1) -> 243.5 | G63: =+ROUND(G62-E63,1) -> 237.6
A64: 60 | B64: 47420 | D64: =+ROUND(G63*0.01,1) -> 2.4 | E64: =ROUNDUP($C$4/60,1)-1.1 -> 237.6 | F64: =+ROUND(D64+E64,1) -> 240 | G64: =+ROUND(G63-E64,1) -> 0
A65: TOTAL | D65: =+SUM(D5:D64) -> 4367.6 | E65: =+SUM(E5:E64) -> 14320.9 | F65: =+SUM(F5:F64) -> 18688.5
A67: SOCIO: MELBA GLADIS CHAVEZ QUEVEDO
A68: OCTUBRE 2024 - PRÉSTAMO
A69: PLAZO | B69: FECHA | C69: PRÉSTAMO S/. | D69: INTERES | E69: ABONO DE CAPITAL | F69: CUOTA | G69: SALDO
A70: 0 | B70: 45686 | C70: =+J73 -> 25740.4 | D70: 0.01 | G70: =+C70 -> 25740.4
A71: 1 | B71: 45716 | D71: =+ROUND(G70*0.01,1) -> 257.4 | E71: =ROUND($C$70/12,1) -> 2145 | F71: =+ROUND(D71+E71,1) -> 2402.4 | G71: =+ROUND(G70-E71,1) -> 23595.4 | I71: SALDO | J71: =G19 -> 10740.4
A72: 2 | B72: 45745 | D72: =+ROUND(G71*0.01,1) -> 236 | E72: =ROUND($C$70/12,1) -> 2145 | F72: =+ROUND(D72+E72,1) -> 2381 | G72: =+ROUND(G71-E72,1) -> 21450.4 | I72: PRESTAMO | J72: 15000
...

Sheet 13
A1: SOCIO: MARIA ELIZABETH CHAVEZ SALAZAR
A2: FEBRERO 2025 - PRÉSTAMO
A3: PLAZO | B3: FECHA | C3: PRÉSTAMO S/. | D3: INTERES | E3: ABONO DE CAPITAL | F3: CUOTA | G3: SALDO
A4: 0 | B4: 29/02/2025 | C4: =+J7 -> 24266 | D4: 0.01 | G4: =+C4 -> 24266
A5: 1 | B5: 45745 | D5: =+ROUND(G4*0.01,1) -> 242.7 | E5: =ROUNDUP(C4/84,1) -> 288.9 | F5: =+ROUND(D5+E5,1) -> 531.6 | G5: =+ROUND(G4-E5,1) -> 23977.1 | I5: SALDO | J5: 14266
A6: 2 | B6: 45776 | D6: =+ROUND(G5*0.01,1) -> 239.8 | E6: =ROUNDUP($C$4/84,1) -> 288.9 | F6: =+ROUND(D6+E6,1) -> 528.7 | G6: =+ROUND(G5-E6,1) -> 23688.2 | I6: PRESTAMO | J6: 10000
A7: 3 | B7: 45806 | D7: =+ROUND(G6*0.01,1) -> 236.9 | E7: =ROUNDUP($C$4/84,1) -> 288.9 | F7: =+ROUND(D7+E7,1) -> 525.8 | G7: =+ROUND(G6-E7,1) -> 23399.3 | I7: TOTAL | J7: =+SUM(J5:J6) -> 24266
A8: 4 | B8: 45837 | D8: =+ROUND(G7*0.01,1) -> 234 | E8: =ROUNDUP($C$4/84,1) -> 288.9 | F8: =+ROUND(D8+E8,1) -> 522.9 | G8: =+ROUND(G7-E8,1) -> 23110.4
A9: 5 | B9: 45867 | D9: =+ROUND(G8*0.01,1) -> 231.1 | E9: =ROUNDUP($C$4/84,1) -> 288.9 | F9: =+ROUND(D9+E9,1) -> 520 | G9: =+ROUND(G8-E9,1) -> 22821.5
A10: 6 | B10: 45898 | D10: =+ROUND(G9*0.01,1) -> 228.2 | E10: =ROUNDUP($C$4/84,1) -> 288.9 | F10: =+ROUND(D10+E10,1) -> 517.1 | G10: =+ROUND(G9-E10,1) -> 22532.6
A11: 7 | B11: 45929 | D11: =+ROUND(G10*0.01,1) -> 225.3 | E11: =ROUNDUP($C$4/84,1) -> 288.9 | F11: =+ROUND(D11+E11,1) -> 514.2 | G11: =+ROUND(G10-E11,1) -> 22243.7
A12: 8 | B12: 45959 | D12: =+ROUND(G11*0.01,1) -> 222.4 | E12: =ROUNDUP($C$4/84,1) -> 288.9 | F12: =+ROUND(D12+E12,1) -> 511.3 | G12: =+ROUND(G11-E12,1) -> 21954.8
A13: 9 | B13: 45990 | D13: =+ROUND(G12*0.01,1) -> 219.5 | E13: =ROUNDUP($C$4/84,1) -> 288.9 | F13: =+ROUND(D13+E13,1) -> 508.4 | G13: =+ROUND(G12-E13,1) -> 21665.9
A14: 10 | B14: 46020 | D14: =+ROUND(G13*0.01,1) -> 216.7 | E14: =ROUNDUP($C$4/84,1) -> 288.9 | F14: =+ROUND(D14+E14,1) -> 505.6 | G14: =+ROUND(G13-E14,1) -> 21377
